Workbook

Sheet อ่านก่อน
A1: ต้นทุนที่รัฐจ่ายให้ข้าราชการ 1 คน ตลอดชีวิต — แบบจำลองเปิดสูตร
A2: สร้างเพื่อตรวจสอบข้ออ้าง “ข้าราชการ 1 คน รัฐจ่ายประมาณ 40 ล้านบาท” (รศ.ดร.สุนิสา ช่อแก้ว, เวทีเสวนา 4 ก.ย. 2569)
A4: ข้อควรรู้ก่อนอื่น: ตัวเลข 40 ล้านที่เป็นข่าว ไม่มีการเผยแพร่วิธีคำนวณ
A5: แหล่งข่าวระบุเพียงนิยามของก้อนเงิน — “ตั้งแต่วันแรกที่บรรจุ จนเกษียณ ได้บำนาญ ได้สวัสดิการ จนกระทั่งเสียชีวิต”
A6: ไม่ได้บอกตำแหน่ง ระดับ อายุราชการ อัตราเงินเฟ้อ หรือวิธีคิดมูลค่าเงิน
A7: แฟ้มนี้จึงเป็นการ “สร้างวิธีคำนวณขึ้นใหม่” จากกฎหมายและอัตราจริงที่ตรวจสอบได้ ไม่ใช่การถอดสูตรของอาจารย์
A9: โครงสร้างแฟ้ม
A10: สมมติฐาน | B10: ค่าตั้งต้นทั้งหมด แยก 3 กรณี — แก้ได้ที่ช่องพื้นเหลือง/ตัวอักษรสีฟ้าเท่านั้น
A11: 1_ต่ำ | B11: ชั้นผู้น้อย ประเภททั่วไป บรรจุอายุ 22 (ปวส.) เกษียณระดับชำนาญงาน เสียชีวิตอายุ 78
A12: 2_กลาง | B12: วิชาการ บรรจุอายุ 25 (ป.ตรี) เกษียณระดับชำนาญการพิเศษ มีคู่สมรส บุตร 2 บิดามารดา 2 เสียชีวิตอายุ 82
A13: 3_สูง | B13: ผู้ใหญ่เทียบซี 9–10 บรรจุอายุ 24 (ป.โท) เกษียณระดับเชี่ยวชาญ/อำนวยการสูง เสียชีวิตอายุ 85
A14: สรุป | B14: เปรียบเทียบ 3 กรณี + กระทบยอดกับตัวเลข 40 ล้าน + ทดสอบความไวต่อเงินเฟ้อ + คูณ 1.7 ล้านคน
A15: แหล่งอ้างอิง | B15: ที่มาของทุกอัตราที่ใช้ พร้อมลิงก์
A17: สีของตัวเลข
A18: พื้นเหลือง + ตัวฟ้า | B18: ค่าที่กรอกเอง (input) — แก้ได้
A19: ตัวดำ | B19: สูตรคำนวณภายในแผ่นเดียวกัน
A20: ตัวเขียว | B20: สูตรที่ดึงค่ามาจากแผ่นอื่น
A22: อ่านผลลัพธ์อย่างไรไม่ให้เข้าใจผิด
A23: 1 | B23: ตัวเลขนี้คือผลรวมเงินสดสะสม 55–62 ปี ไม่ใช่รายจ่ายต่อปี — เอาไปเทียบกับงบประมาณปีเดียวไม่ได้
A24: 2 | B24: แผ่นคำนวณให้ 3 คำตอบที่ต่างกันได้เกือบเท่าตัว: (ก) ตัวเงินจริงในอนาคต (ข) ราคาปี 2569 (ค) มูลค่าปัจจุบัน
B25: ตัวเลข 40 ล้านจะ 'สมเหตุสมผล' หรือ 'เกินจริง' ขึ้นอยู่กับว่าใช้นิยามไหน — นี่คือประเด็นสำคัญที่สุดของแฟ้มนี้
A26: 3 | B26: เป็นด้านรายจ่ายล้วน ไม่ได้หักภาษีเงินได้ที่ข้าราชการจ่ายคืนรัฐ และไม่ได้ตีมูลค่าบริการสาธารณะที่ผลิตออกมา
A27: 4 | B27: ไม่รวมค่าสำนักงาน ครุภัณฑ์ ค่าฝึกอบรม ซึ่งเป็นต้นทุนของรัฐเช่นกัน — ตัวเลขจริงจึงสูงกว่านี้อีก
A28: 5 | B28: ค่าเฉลี่ยกลบความต่างมหาศาล: กรณีต่ำมีต้นทุนไม่ถึงครึ่งของกรณีสูง การพูดว่า 'เฉลี่ยคนละ 40 ล้าน' จึงบอกอะไรได้จำกัด

Sheet สมมติฐาน
A1: สมมติฐานทั้งหมด
A2: ราคาทุกรายการเป็น 'ราคาปี 2569' เว้นแต่ระบุ • แก้เฉพาะช่องพื้นเหลือง • แก้แล้วต้องกด Ctrl+Shift+F9 (หรือเปิด-ปิดใหม่) ให้สูตรคำนวณใหม่
A4: รายการ | B4: ต่ำ (ผู้น้อย) | C4: กลาง | D4: สูง (ซี 9–10) | E4: หน่วย | F4: ที่มา / เหตุผล
A5: โครงร่างอาชีพ
A6: ประเภท/ระดับตอนเกษียณ | B6: ทั่วไป – ชำนาญงาน | C6: วิชาการ – ชำนาญการพิเศษ | D6: เชี่ยวชาญ / อำนวยการสูง | F6: พ.ร.บ.ระเบียบข้าราชการพลเรือน พ.ศ. 2551
A7: อายุแรกบรรจุ | B7: 22 | C7: 25 | D7: 24 | E7: ปี | F7: ต่ำ = วุฒิ ปวส. / กลาง = ป.ตรี / สูง = ป.โท
A8: อายุเกษียณ | B8: 60 | C8: 60 | D8: 60 | E8: ปี | F8: เกษียณอายุราชการปกติ
A9: อายุที่เสียชีวิต | B9: 78 | C9: 82 | D9: 85 | E9: ปี | F9: อายุคาดเฉลี่ยของคนไทยเมื่ออายุ 60 ปี ประมาณ 80–85 ปี ผู้มีสิทธิรักษาพยาบาลดีมักสูงกว่าค่าเฉลี่ย
A10: อายุราชการ | B10: =B8-B7 -> 38 | C10: =C8-C7 -> 35 | D10: =D8-D7 -> 36 | E10: ปี | F10: อายุเกษียณ − อายุแรกบรรจุ
A11: จำนวนปีรับบำนาญ | B11: =B9-B8+1 -> 19 | C11: =C9-C8+1 -> 23 | D11: =D9-D8+1 -> 26 | E11: ปี | F11: อายุเสียชีวิต − อายุเกษียณ + 1
A12: เงินเดือนและเงินเพิ่ม
A13: เงินเดือนแรกบรรจุ | B13: 13920 | C13: 18220 | D13: 21180 | E13: บาท/เดือน | F13: อัตราแรกบรรจุ 1 พ.ค. 2568 (สำนักงาน ก.พ.): ปวส. 13,920 / ป.ตรี 18,220 / ป.โท 21,180
A14: เงินเดือนเดือนสุดท้ายก่อนเกษียณ | B14: 36000 | C14: 52000 | D14: 74000 | E14: บาท/เดือน | F14: เพดานบัญชีเงินเดือน: ชำนาญงาน 38,750 / ชำนาญการพิเศษ 58,390 / เชี่ยวชาญ 69,040 / อำนวยการสูง 76,800
A15: อัตราเติบโตเงินเดือนที่แท้จริง | B15: =(B14/B13)^(1/(B10-1))-1 -> 0.026013467 | C15: =(C14/C13)^(1/(C10-1))-1 -> 0.031325449 | D15: =(D14/D13)^(1/(D10-1))-1 -> 0.036389542 | E15: %/ปี | F15: คำนวณย้อนกลับจากเงินเดือนต้น–ปลาย ไม่รวมเงินเฟ้อ (ระบบเลื่อนขั้น 2–6%/ปี ตามผลงาน)
A16: เงินประจำตำแหน่ง ระยะที่ 1 | B16: 0 | C16: 3500 | D16: 5600 | E16: บาท/เดือน | F16: ชำนาญการ 3,500 / ชำนาญการพิเศษ 5,600 — ประเภททั่วไประดับชำนาญงานไม่มีเงินประจำตำแหน่ง
A17: เริ่มปีราชการที่ (ระยะ 1) | B17: 999 | C17: 8 | D17: 12 | E17: ปีที่ | F17: ใส่ 999 = ไม่ได้รับ
A18: เงินประจำตำแหน่ง ระยะที่ 2 | B18: 0 | C18: 5600 | D18: 20000 | E18: บาท/เดือน | F18: กรณีสูง = เงินประจำตำแหน่ง 10,000 + ค่าตอบแทนรายเดือนอีก 10,000 (อำนวยการสูง/เชี่ยวชาญ)
A19: เริ่มปีราชการที่ (ระยะ 2) | B19: 999 | C19: 20 | D19: 24 | E19: ปีที่
A20: ค่าตอบแทน/สวัสดิการอื่น | B20: 0.03 | C20: 0.03 | D20: 0.04 | E20: % ของเงินเดือน | F20: ค่าล่วงเวลา เบี้ยประชุม ค่าเดินทางไปราชการ เครื่องแบบ ฯลฯ — ประมาณการ ไม่มีสถิติรวมเผยแพร่
A21: เงินสมทบ กบข. ที่รัฐจ่าย | B21: 0.05 | C21: 0.05 | D21: 0.05 | E21: % ของเงินเดือน | F21: เงินสมทบ 3% + เงินชดเชย 2% ตาม พ.ร.บ.กองทุนบำเหน็จบำนาญข้าราชการ พ.ศ. 2539
A22: ค่าเช่าบ้านราชการ | B22: 0 | C22: 4000 | D22: 5000 | E22: บาท/เดือน | F22: เบิกได้เฉพาะผู้ไม่มีเคหสถานของตนเองในท้องที่ที่ประจำการ
A23: จำนวนปีที่เบิก | B23: 0 | C23: 10 | D23: 12 | E23: ปี
A24: สวัสดิการครอบครัว
A25: ค่าการศึกษาบุตร | B25: 12000 | C25: 25000 | D25: 25000 | E25: บาท/ปี/คน | F25: เบิกได้ไม่เกิน 3 คน จนจบปริญญาตรี อัตราขึ้นกับประเภทสถานศึกษา
A26: จำนวนบุตร | B26: 1 | C26: 2 | D26: 2 | E26: คน
A27: ปีราชการที่เริ่มเบิก | B27: 10 | C27: 8 | D27: 8 | E27: ปีที่
A28: จำนวนปีที่เบิก | B28: 15 | C28: 18 | D28: 18 | E28: ปี
A29: ค่ารักษาพยาบาล (สิทธิเบิกจ่ายตรง)
A30: ผู้ใช้สิทธิวัยไม่สูงอายุ: ตนเอง + คู่สมรส | B30: 1 | C30: 2 | D30: 2 | E30: คน | F30: กรณีต่ำสมมติคู่สมรสมีสิทธิของตนเอง จึงนับเฉพาะตัวข้าราชการ
A31: บุตรที่ใช้สิทธิ | B31: 1 | C31: 2 | D31: 2 | E31: คน | F31: บุตรใช้สิทธิได้จนอายุ 20 ปี
A32: ปีราชการที่บุตรเริ่มใช้สิทธิ | B32: 10 | C32: 8 | D32: 8 | E32: ปีที่
A33: ปีราชการที่บุตรสิ้นสุดสิทธิ | B33: 29 | C33: 27 | D33: 27 | E33: ปีที่
A34: ผู้ใช้สิทธิสูงอายุ: บิดามารดา | B34: 1 | C34: 2 | D34: 2 | E34: คน | F34: เบิกให้บิดามารดาของตนได้ (เบิกให้พ่อแม่ของคู่สมรสไม่ได้)
A35: ปีราชการที่เริ่มใช้สิทธิ | B35: 1 | C35: 1 | D35: 1 | E35: ปีที่
A36: ปีราชการที่สิ้นสุด (บิดามารดาเสียชีวิต) | B36: 20 | C36: 22 | D36: 22 | E36: ปีที่
A37: ผู้ใช้สิทธิหลังเกษียณ | B37: 1 | C37: 2 | D37: 2 | E37: คน | F37: ตนเอง + คู่สมรส ใช้สิทธิต่อได้ตลอดชีวิตผู้รับบำนาญ
A38: ค่ารักษา/คน/ปี — วัยไม่สูงอายุ | B38: 8000 | C38: 8000 | D38: 9000 | E38: บาท/ปี | F38: สอบเทียบกับยอดเบิกจริงทั้งระบบ 1.06 แสนล้านบาท ต่อผู้มีสิทธิ ~5 ล้านคน ≈ 21,000 บาท/คน/ปี
A39: ค่ารักษา/คน/ปี — สูงอายุ 60 ปีขึ้นไป | B39: 25000 | C39: 25000 | D39: 28000 | E39: บาท/ปี | F39: ผู้สูงอายุใช้จ่ายสูงกว่าค่าเฉลี่ยมาก จากกลุ่มโรค NCDs และค่ายา (กรมบัญชีกลาง)
A41: สมมติฐานร่วม (ใช้กับทั้ง 3 กรณี)
A42: ปีฐาน (พ.ศ.) ที่เริ่มบรรจุ | B42: 2569 | F42: สมมติว่าบรรจุปีนี้ เพื่อให้เห็นภาระในอนาคตของคนที่เพิ่งเข้าระบบ
...

Sheet 1_ต่ำ
A1: กรณี ต่ำ — ข้าราชการชั้นผู้น้อย — ประเภททั่วไป เกษียณระดับชำนาญงาน
A2: ทุกจำนวนเงินเป็น 'ตัวเงินจริง ณ ปีนั้น' (nominal) เว้นคอลัมน์ที่ระบุไว้ • แก้สมมติฐานได้ที่แผ่น 'สมมติฐาน' เท่านั้น • ตัวแปรบำนาญคำนวณไว้ทางขวามือ | Y2: ตัวแปรบำนาญ (คำนวณจากตารางด้านล่าง)
Y3: เงินเดือนเฉลี่ย 60 เดือนสุดท้าย | AB3: =AVERAGE(F42:F46) -> 68533.109
Y4: บำนาญรายเดือน | AB4: =MIN(AB3*สมมติฐาน!$B$10/สมมติฐาน!$B$48,AB3*สมมติฐาน!$B$47) -> 47973.176
Y5: ช.ค.บ. รายเดือน | AB5: =MAX(0,สมมติฐาน!$B$49-AB4) -> 0
Y6: บำนาญ + ช.ค.บ. รายเดือน | AB6: =AB4+AB5 -> 47973.176
Y7: บำเหน็จดำรงชีพ ครั้งที่ 1 (ปีเกษียณ) | AB7: =MIN(AB4*สมมติฐาน!$B$52,สมมติฐาน!$B$50) -> 200000
A8: ปีที่ | B8: ปี พ.ศ. | C8: อายุ | D8: สถานะ | E8: ดัชนีราคา | F8: เงินเดือน (บาท/เดือน) | G8: เงินเดือน รายปี | H8: เงินประจำตำแหน่ง + ค่าตอบแทน | I8: เงินสมทบ กบข. (รัฐจ่าย) | J8: ค่าเช่าบ้าน | K8: ค่าการศึกษา บุตร | L8: ค่าตอบแทน/ สวัสดิการอื่น | M8: ผู้ใช้สิทธิ ไม่สูงอายุ | N8: ผู้ใช้สิทธิ สูงอายุ | O8: ดัชนี ค่ารักษา | P8: ค่ารักษาพยาบาล | Q8: บำนาญ + ช.ค.บ. | R8: เงินก้อน (ดำรงชีพ/ตกทอด/ค่าทำศพ) | S8: รวมต้นทุนปีนั้น (ตัวเงินจริง) | T8: รวม ณ ราคาปี 2569 | U8: ตัวคิดลด | V8: มูลค่าปัจจุบัน | Y8: บำเหน็จดำรงชีพ รวมทั้งหมด | AB8: =MIN(AB4*สมมติฐาน!$B$52,สมมติฐาน!$B$51) -> 500000
A9: 1 | B9: =สมมติฐาน!$B$42+A9-1 -> 2569 | C9: =สมมติฐาน!$B$7+A9-1 -> 22 | D9: =IF(C9<สมมติฐาน!$B$8,"รับราชการ","รับบำนาญ") -> รับราชการ | E9: =(1+สมมติฐาน!$B$43)^(A9-1) -> 1 | F9: =IF(D9="รับราชการ",สมมติฐาน!$B$13*(1+สมมติฐาน!$B$15)^(A9-1)*E9,0) -> 13920 | G9: =F9*12 -> 167040 | H9: =IF(D9="รับราชการ",IF(A9>=สมมติฐาน!$B$19,สมมติฐาน!$B$18,IF(A9>=สมมติฐาน!$B$17,สมมติฐาน!$B$16,0))*12*E9,0) -> 0 | I9: =G9*สมมติฐาน!$B$21 -> 8352 | J9: =IF(AND(D9="รับราชการ",A9<=สมมติฐาน!$B$23),สมมติฐาน!$B$22*12*E9,0) -> 0 | K9: =IF(AND(D9="รับราชการ",A9>=สมมติฐาน!$B$27,A9<สมมติฐาน!$B$27+สมมติฐาน!$B$28),สมมติฐาน!$B$25*สมมติฐาน!$B$26*E9,0) -> 0 | L9: =G9*สมมติฐาน!$B$20 -> 5011.2 | M9: =IF(D9="รับราชการ",สมมติฐาน!$B$30+IF(AND(A9>=สมมติฐาน!$B$32,A9<=สมมติฐาน!$B$33),สมมติฐาน!$B$31,0),0) -> 1 | N9: =IF(AND(A9>=สมมติฐาน!$B$35,A9<=สมมติฐาน!$B$36),สมมติฐาน!$B$34,0)+IF(D9="รับราชการ",0,สมมติฐาน!$B$37) -> 1 | O9: =(1+สมมติฐาน!$B$43)^(A9-1)*(1+สมมติฐาน!$B$44)^(A9-1) -> 1 | P9: =(M9*สมมติฐาน!$B$38+N9*สมมติฐาน!$B$39)*O9 -> 33000 | Q9: =IF(D9="รับราชการ",0,$AB$6*12*(1+สมมติฐาน!$B$46)^(A9-38-1)) -> 0 | R9: =IF(C9=สมมติฐาน!$B$8,$AB$7,0)+IF(C9=65,$AB$9,0)+IF(A9=57,$AB$10+$AB$11,0) -> 0 | S9: =G9+H9+I9+J9+K9+L9+P9+Q9+R9 -> 213403.2 | T9: =S9/E9 -> 213403.2 | U9: =1/(1+สมมติฐาน!$B$45)^(A9-1) -> 1 | V9: =S9*U9 -> 213403.2 | Y9: บำเหน็จดำรงชีพ ครั้งที่ 2 (อายุ 65) | AB9: =AB8-AB7 -> 300000
A10: 2 | B10: =สมมติฐาน!$B$42+A10-1 -> 2570 | C10: =สมมติฐาน!$B$7+A10-1 -> 23 | D10: =IF(C10<สมมติฐาน!$B$8,"รับราชการ","รับบำนาญ") -> รับราชการ | E10: =(1+สมมติฐาน!$B$43)^(A10-1) -> 1.02 | F10: =IF(D10="รับราชการ",สมมติฐาน!$B$13*(1+สมมติฐาน!$B$15)^(A10-1)*E10,0) -> 14567.75 | G10: =F10*12 -> 174813 | H10: =IF(D10="รับราชการ",IF(A10>=สมมติฐาน!$B$19,สมมติฐาน!$B$18,IF(A10>=สมมติฐาน!$B$17,สมมติฐาน!$B$16,0))*12*E10,0) -> 0 | I10: =G10*สมมติฐาน!$B$21 -> 8740.6498 | J10: =IF(AND(D10="รับราชการ",A10<=สมมติฐาน!$B$23),สมมติฐาน!$B$22*12*E10,0) -> 0 | K10: =IF(AND(D10="รับราชการ",A10>=สมมติฐาน!$B$27,A10<สมมติฐาน!$B$27+สมมติฐาน!$B$28),สมมติฐาน!$B$25*สมมติฐาน!$B$26*E10,0) -> 0 | L10: =G10*สมมติฐาน!$B$20 -> 5244.3899 | M10: =IF(D10="รับราชการ",สมมติฐาน!$B$30+IF(AND(A10>=สมมติฐาน!$B$32,A10<=สมมติฐาน!$B$33),สมมติฐาน!$B$31,0),0) -> 1 | N10: =IF(AND(A10>=สมมติฐาน!$B$35,A10<=สมมติฐาน!$B$36),สมมติฐาน!$B$34,0)+IF(D10="รับราชการ",0,สมมติฐาน!$B$37) -> 1 | O10: =(1+สมมติฐาน!$B$43)^(A10-1)*(1+สมมติฐาน!$B$44)^(A10-1) -> 1.0404 | P10: =(M10*สมมติฐาน!$B$38+N10*สมมติฐาน!$B$39)*O10 -> 34333.2 | Q10: =IF(D10="รับราชการ",0,$AB$6*12*(1+สมมติฐาน!$B$46)^(A10-38-1)) -> 0 | R10: =IF(C10=สมมติฐาน!$B$8,$AB$7,0)+IF(C10=65,$AB$9,0)+IF(A10=57,$AB$10+$AB$11,0) -> 0 | S10: =G10+H10+I10+J10+K10+L10+P10+Q10+R10 -> 223131.23 | T10: =S10/E10 -> 218756.11 | U10: =1/(1+สมมติฐาน!$B$45)^(A10-1) -> 0.96153846 | V10: =S10*U10 -> 214549.26 | Y10: บำเหน็จตกทอด (ปีเสียชีวิต) | AB10: =MAX(0,AB6*สมมติฐาน!$B$53-AB8) -> 939195.29
A11: 3 | B11: =สมมติฐาน!$B$42+A11-1 -> 2571 | C11: =สมมติฐาน!$B$7+A11-1 -> 24 | D11: =IF(C11<สมมติฐาน!$B$8,"รับราชการ","รับบำนาญ") -> รับราชการ | E11: =(1+สมมติฐาน!$B$43)^(A11-1) -> 1.0404 | F11: =IF(D11="รับราชการ",สมมติฐาน!$B$13*(1+สมมติฐาน!$B$15)^(A11-1)*E11,0) -> 15245.641 | G11: =F11*12 -> 182947.7 | H11: =IF(D11="รับราชการ",IF(A11>=สมมติฐาน!$B$19,สมมติฐาน!$B$18,IF(A11>=สมมติฐาน!$B$17,สมมติฐาน!$B$16,0))*12*E11,0) -> 0 | I11: =G11*สมมติฐาน!$B$21 -> 9147.3849 | J11: =IF(AND(D11="รับราชการ",A11<=สมมติฐาน!$B$23),สมมติฐาน!$B$22*12*E11,0) -> 0 | K11: =IF(AND(D11="รับราชการ",A11>=สมมติฐาน!$B$27,A11<สมมติฐาน!$B$27+สมมติฐาน!$B$28),สมมติฐาน!$B$25*สมมติฐาน!$B$26*E11,0) -> 0 | L11: =G11*สมมติฐาน!$B$20 -> 5488.4309 | M11: =IF(D11="รับราชการ",สมมติฐาน!$B$30+IF(AND(A11>=สมมติฐาน!$B$32,A11<=สมมติฐาน!$B$33),สมมติฐาน!$B$31,0),0) -> 1 | N11: =IF(AND(A11>=สมมติฐาน!$B$35,A11<=สมมติฐาน!$B$36),สมมติฐาน!$B$34,0)+IF(D11="รับราชการ",0,สมมติฐาน!$B$37) -> 1 | O11: =(1+สมมติฐาน!$B$43)^(A11-1)*(1+สมมติฐาน!$B$44)^(A11-1) -> 1.0824322 | P11: =(M11*สมมติฐาน!$B$38+N11*สมมติฐาน!$B$39)*O11 -> 35720.261 | Q11: =IF(D11="รับราชการ",0,$AB$6*12*(1+สมมติฐาน!$B$46)^(A11-38-1)) -> 0 | R11: =IF(C11=สมมติฐาน!$B$8,$AB$7,0)+IF(C11=65,$AB$9,0)+IF(A11=57,$AB$10+$AB$11,0) -> 0 | S11: =G11+H11+I11+J11+K11+L11+P11+Q11+R11 -> 233303.77 | T11: =S11/E11 -> 224244.3 | U11: =1/(1+สมมติฐาน!$B$45)^(A11-1) -> 0.92455621 | V11: =S11*U11 -> 215702.45 | Y11: เงินช่วยพิเศษ ค่าทำศพ (ปีเสียชีวิต) | AB11: =AB6*สมมติฐาน!$B$54 -> 143919.53
A12: 4 | B12: =สมมติฐาน!$B$42+A12-1 -> 2572 | C12: =สมมติฐาน!$B$7+A12-1 -> 25 | D12: =IF(C12<สมมติฐาน!$B$8,"รับราชการ","รับบำนาญ") -> รับราชการ | E12: =(1+สมมติฐาน!$B$43)^(A12-1) -> 1.061208 | F12: =IF(D12="รับราชการ",สมมติฐาน!$B$13*(1+สมมติฐาน!$B$15)^(A12-1)*E12,0) -> 15955.078 | G12: =F12*12 -> 191460.94 | H12: =IF(D12="รับราชการ",IF(A12>=สมมติฐาน!$B$19,สมมติฐาน!$B$18,IF(A12>=สมมติฐาน!$B$17,สมมติฐาน!$B$16,0))*12*E12,0) -> 0 | I12: =G12*สมมติฐาน!$B$21 -> 9573.0469 | J12: =IF(AND(D12="รับราชการ",A12<=สมมติฐาน!$B$23),สมมติฐาน!$B$22*12*E12,0) -> 0 | K12: =IF(AND(D12="รับราชการ",A12>=สมมติฐาน!$B$27,A12<สมมติฐาน!$B$27+สมมติฐาน!$B$28),สมมติฐาน!$B$25*สมมติฐาน!$B$26*E12,0) -> 0 | L12: =G12*สมมติฐาน!$B$20 -> 5743.8281 | M12: =IF(D12="รับราชการ",สมมติฐาน!$B$30+IF(AND(A12>=สมมติฐาน!$B$32,A12<=สมมติฐาน!$B$33),สมมติฐาน!$B$31,0),0) -> 1 | N12: =IF(AND(A12>=สมมติฐาน!$B$35,A12<=สมมติฐาน!$B$36),สมมติฐาน!$B$34,0)+IF(D12="รับราชการ",0,สมมติฐาน!$B$37) -> 1 | O12: =(1+สมมติฐาน!$B$43)^(A12-1)*(1+สมมติฐาน!$B$44)^(A12-1) -> 1.1261624 | P12: =(M12*สมมติฐาน!$B$38+N12*สมมติฐาน!$B$39)*O12 -> 37163.36 | Q12: =IF(D12="รับราชการ",0,$AB$6*12*(1+สมมติฐาน!$B$46)^(A12-38-1)) -> 0 | R12: =IF(C12=สมมติฐาน!$B$8,$AB$7,0)+IF(C12=65,$AB$9,0)+IF(A12=57,$AB$10+$AB$11,0) -> 0 | S12: =G12+H12+I12+J12+K12+L12+P12+Q12+R12 -> 243941.17 | T12: =S12/E12 -> 229871.21 | U12: =1/(1+สมมติฐาน!$B$45)^(A12-1) -> 0.88899636 | V12: =S12*U12 -> 216862.81
A13: 5 | B13: =สมมติฐาน!$B$42+A13-1 -> 2573 | C13: =สมมติฐาน!$B$7+A13-1 -> 26 | D13: =IF(C13<สมมติฐาน!$B$8,"รับราชการ","รับบำนาญ") -> รับราชการ | E13: =(1+สมมติฐาน!$B$43)^(A13-1) -> 1.0824322 | F13: =IF(D13="รับราชการ",สมมติฐาน!$B$13*(1+สมมติฐาน!$B$15)^(A13-1)*E13,0) -> 16697.527 | G13: =F13*12 -> 200370.33 | H13: =IF(D13="รับราชการ",IF(A13>=สมมติฐาน!$B$19,สมมติฐาน!$B$18,IF(A13>=สมมติฐาน!$B$17,สมมติฐาน!$B$16,0))*12*E13,0) -> 0 | I13: =G13*สมมติฐาน!$B$21 -> 10018.516 | J13: =IF(AND(D13="รับราชการ",A13<=สมมติฐาน!$B$23),สมมติฐาน!$B$22*12*E13,0) -> 0 | K13: =IF(AND(D13="รับราชการ",A13>=สมมติฐาน!$B$27,A13<สมมติฐาน!$B$27+สมมติฐาน!$B$28),สมมติฐาน!$B$25*สมมติฐาน!$B$26*E13,0) -> 0 | L13: =G13*สมมติฐาน!$B$20 -> 6011.1099 | M13: =IF(D13="รับราชการ",สมมติฐาน!$B$30+IF(AND(A13>=สมมติฐาน!$B$32,A13<=สมมติฐาน!$B$33),สมมติฐาน!$B$31,0),0) -> 1 | N13: =IF(AND(A13>=สมมติฐาน!$B$35,A13<=สมมติฐาน!$B$36),สมมติฐาน!$B$34,0)+IF(D13="รับราชการ",0,สมมติฐาน!$B$37) -> 1 | O13: =(1+สมมติฐาน!$B$43)^(A13-1)*(1+สมมติฐาน!$B$44)^(A13-1) -> 1.1716594 | P13: =(M13*สมมติฐาน!$B$38+N13*สมมติฐาน!$B$39)*O13 -> 38664.76 | Q13: =IF(D13="รับราชการ",0,$AB$6*12*(1+สมมติฐาน!$B$46)^(A13-38-1)) -> 0 | R13: =IF(C13=สมมติฐาน!$B$8,$AB$7,0)+IF(C13=65,$AB$9,0)+IF(A13=57,$AB$10+$AB$11,0) -> 0 | S13: =G13+H13+I13+J13+K13+L13+P13+Q13+R13 -> 255064.72 | T13: =S13/E13 -> 235640.37 | U13: =1/(1+สมมติฐาน!$B$45)^(A13-1) -> 0.85480419 | V13: =S13*U13 -> 218030.39
A14: 6 | B14: =สมมติฐาน!$B$42+A14-1 -> 2574 | C14: =สมมติฐาน!$B$7+A14-1 -> 27 | D14: =IF(C14<สมมติฐาน!$B$8,"รับราชการ","รับบำนาญ") -> รับราชการ | E14: =(1+สมมติฐาน!$B$43)^(A14-1) -> 1.1040808 | F14: =IF(D14="รับราชการ",สมมติฐาน!$B$13*(1+สมมติฐาน!$B$15)^(A14-1)*E14,0) -> 17474.526 | G14: =F14*12 -> 209694.31 | H14: =IF(D14="รับราชการ",IF(A14>=สมมติฐาน!$B$19,สมมติฐาน!$B$18,IF(A14>=สมมติฐาน!$B$17,สมมติฐาน!$B$16,0))*12*E14,0) -> 0 | I14: =G14*สมมติฐาน!$B$21 -> 10484.716 | J14: =IF(AND(D14="รับราชการ",A14<=สมมติฐาน!$B$23),สมมติฐาน!$B$22*12*E14,0) -> 0 | K14: =IF(AND(D14="รับราชการ",A14>=สมมติฐาน!$B$27,A14<สมมติฐาน!$B$27+สมมติฐาน!$B$28),สมมติฐาน!$B$25*สมมติฐาน!$B$26*E14,0) -> 0 | L14: =G14*สมมติฐาน!$B$20 -> 6290.8293 | M14: =IF(D14="รับราชการ",สมมติฐาน!$B$30+IF(AND(A14>=สมมติฐาน!$B$32,A14<=สมมติฐาน!$B$33),สมมติฐาน!$B$31,0),0) -> 1 | N14: =IF(AND(A14>=สมมติฐาน!$B$35,A14<=สมมติฐาน!$B$36),สมมติฐาน!$B$34,0)+IF(D14="รับราชการ",0,สมมติฐาน!$B$37) -> 1 | O14: =(1+สมมติฐาน!$B$43)^(A14-1)*(1+สมมติฐาน!$B$44)^(A14-1) -> 1.2189944 | P14: =(M14*สมมติฐาน!$B$38+N14*สมมติฐาน!$B$39)*O14 -> 40226.816 | Q14: =IF(D14="รับราชการ",0,$AB$6*12*(1+สมมติฐาน!$B$46)^(A14-38-1)) -> 0 | R14: =IF(C14=สมมติฐาน!$B$8,$AB$7,0)+IF(C14=65,$AB$9,0)+IF(A14=57,$AB$10+$AB$11,0) -> 0 | S14: =G14+H14+I14+J14+K14+L14+P14+Q14+R14 -> 266696.67 | T14: =S14/E14 -> 241555.39 | U14: =1/(1+สมมติฐาน!$B$45)^(A14-1) -> 0.82192711 | V14: =S14*U14 -> 219205.22
A15: 7 | B15: =สมมติฐาน!$B$42+A15-1 -> 2575 | C15: =สมมติฐาน!$B$7+A15-1 -> 28 | D15: =IF(C15<สมมติฐาน!$B$8,"รับราชการ","รับบำนาญ") -> รับราชการ | E15: =(1+สมมติฐาน!$B$43)^(A15-1) -> 1.1261624 | F15: =IF(D15="รับราชการ",สมมติฐาน!$B$13*(1+สมมติฐาน!$B$15)^(A15-1)*E15,0) -> 18287.681 | G15: =F15*12 -> 219452.17 | H15: =IF(D15="รับราชการ",IF(A15>=สมมติฐาน!$B$19,สมมติฐาน!$B$18,IF(A15>=สมมติฐาน!$B$17,สมมติฐาน!$B$16,0))*12*E15,0) -> 0 | I15: =G15*สมมติฐาน!$B$21 -> 10972.608 | J15: =IF(AND(D15="รับราชการ",A15<=สมมติฐาน!$B$23),สมมติฐาน!$B$22*12*E15,0) -> 0 | K15: =IF(AND(D15="รับราชการ",A15>=สมมติฐาน!$B$27,A15<สมมติฐาน!$B$27+สมมติฐาน!$B$28),สมมติฐาน!$B$25*สมมติฐาน!$B$26*E15,0) -> 0 | L15: =G15*สมมติฐาน!$B$20 -> 6583.5651 | M15: =IF(D15="รับราชการ",สมมติฐาน!$B$30+IF(AND(A15>=สมมติฐาน!$B$32,A15<=สมมติฐาน!$B$33),สมมติฐาน!$B$31,0),0) -> 1 | N15: =IF(AND(A15>=สมมติฐาน!$B$35,A15<=สมมติฐาน!$B$36),สมมติฐาน!$B$34,0)+IF(D15="รับราชการ",0,สมมติฐาน!$B$37) -> 1 | O15: =(1+สมมติฐาน!$B$43)^(A15-1)*(1+สมมติฐาน!$B$44)^(A15-1) -> 1.2682418 | P15: =(M15*สมมติฐาน!$B$38+N15*สมมติฐาน!$B$39)*O15 -> 41851.979 | Q15: =IF(D15="รับราชการ",0,$AB$6*12*(1+สมมติฐาน!$B$46)^(A15-38-1)) -> 0 | R15: =IF(C15=สมมติฐาน!$B$8,$AB$7,0)+IF(C15=65,$AB$9,0)+IF(A15=57,$AB$10+$AB$11,0) -> 0 | S15: =G15+H15+I15+J15+K15+L15+P15+Q15+R15 -> 278860.32 | T15: =S15/E15 -> 247619.99 | U15: =1/(1+สมมติฐาน!$B$45)^(A15-1) -> 0.79031453 | V15: =S15*U15 -> 220387.36
A16: 8 | B16: =สมมติฐาน!$B$42+A16-1 -> 2576 | C16: =สมมติฐาน!$B$7+A16-1 -> 29 | D16: =IF(C16<สมมติฐาน!$B$8,"รับราชการ","รับบำนาญ") -> รับราชการ | E16: =(1+สมมติฐาน!$B$43)^(A16-1) -> 1.1486857 | F16: =IF(D16="รับราชการ",สมมติฐาน!$B$13*(1+สมมติฐาน!$B$15)^(A16-1)*E16,0) -> 19138.675 | G16: =F16*12 -> 229664.1 | H16: =IF(D16="รับราชการ",IF(A16>=สมมติฐาน!$B$19,สมมติฐาน!$B$18,IF(A16>=สมมติฐาน!$B$17,สมมติฐาน!$B$16,0))*12*E16,0) -> 0 | I16: =G16*สมมติฐาน!$B$21 -> 11483.205 | J16: =IF(AND(D16="รับราชการ",A16<=สมมติฐาน!$B$23),สมมติฐาน!$B$22*12*E16,0) -> 0 | K16: =IF(AND(D16="รับราชการ",A16>=สมมติฐาน!$B$27,A16<สมมติฐาน!$B$27+สมมติฐาน!$B$28),สมมติฐาน!$B$25*สมมติฐาน!$B$26*E16,0) -> 0 | L16: =G16*สมมติฐาน!$B$20 -> 6889.923 | M16: =IF(D16="รับราชการ",สมมติฐาน!$B$30+IF(AND(A16>=สมมติฐาน!$B$32,A16<=สมมติฐาน!$B$33),สมมติฐาน!$B$31,0),0) -> 1 | N16: =IF(AND(A16>=สมมติฐาน!$B$35,A16<=สมมติฐาน!$B$36),สมมติฐาน!$B$34,0)+IF(D16="รับราชการ",0,สมมติฐาน!$B$37) -> 1 | O16: =(1+สมมติฐาน!$B$43)^(A16-1)*(1+สมมติฐาน!$B$44)^(A16-1) -> 1.3194788 | P16: =(M16*สมมติฐาน!$B$38+N16*สมมติฐาน!$B$39)*O16 -> 43542.799 | Q16: =IF(D16="รับราชการ",0,$AB$6*12*(1+สมมติฐาน!$B$46)^(A16-38-1)) -> 0 | R16: =IF(C16=สมมติฐาน!$B$8,$AB$7,0)+IF(C16=65,$AB$9,0)+IF(A16=57,$AB$10+$AB$11,0) -> 0 | S16: =G16+H16+I16+J16+K16+L16+P16+Q16+R16 -> 291580.03 | T16: =S16/E16 -> 253837.96 | U16: =1/(1+สมมติฐาน!$B$45)^(A16-1) -> 0.75991781 | V16: =S16*U16 -> 221576.86
A17: 9 | B17: =สมมติฐาน!$B$42+A17-1 -> 2577 | C17: =สมมติฐาน!$B$7+A17-1 -> 30 | D17: =IF(C17<สมมติฐาน!$B$8,"รับราชการ","รับบำนาญ") -> รับราชการ | E17: =(1+สมมติฐาน!$B$43)^(A17-1) -> 1.1716594 | F17: =IF(D17="รับราชการ",สมมติฐาน!$B$13*(1+สมมติฐาน!$B$15)^(A17-1)*E17,0) -> 20029.269 | G17: =F17*12 -> 240351.23 | H17: =IF(D17="รับราชการ",IF(A17>=สมมติฐาน!$B$19,สมมติฐาน!$B$18,IF(A17>=สมมติฐาน!$B$17,สมมติฐาน!$B$16,0))*12*E17,0) -> 0 | I17: =G17*สมมติฐาน!$B$21 -> 12017.561 | J17: =IF(AND(D17="รับราชการ",A17<=สมมติฐาน!$B$23),สมมติฐาน!$B$22*12*E17,0) -> 0 | K17: =IF(AND(D17="รับราชการ",A17>=สมมติฐาน!$B$27,A17<สมมติฐาน!$B$27+สมมติฐาน!$B$28),สมมติฐาน!$B$25*สมมติฐาน!$B$26*E17,0) -> 0 | L17: =G17*สมมติฐาน!$B$20 -> 7210.5368 | M17: =IF(D17="รับราชการ",สมมติฐาน!$B$30+IF(AND(A17>=สมมติฐาน!$B$32,A17<=สมมติฐาน!$B$33),สมมติฐาน!$B$31,0),0) -> 1 | N17: =IF(AND(A17>=สมมติฐาน!$B$35,A17<=สมมติฐาน!$B$36),สมมติฐาน!$B$34,0)+IF(D17="รับราชการ",0,สมมติฐาน!$B$37) -> 1 | O17: =(1+สมมติฐาน!$B$43)^(A17-1)*(1+สมมติฐาน!$B$44)^(A17-1) -> 1.3727857 | P17: =(M17*สมมติฐาน!$B$38+N17*สมมติฐาน!$B$39)*O17 -> 45301.928 | Q17: =IF(D17="รับราชการ",0,$AB$6*12*(1+สมมติฐาน!$B$46)^(A17-38-1)) -> 0 | R17: =IF(C17=สมมติฐาน!$B$8,$AB$7,0)+IF(C17=65,$AB$9,0)+IF(A17=57,$AB$10+$AB$11,0) -> 0 | S17: =G17+H17+I17+J17+K17+L17+P17+Q17+R17 -> 304881.25 | T17: =S17/E17 -> 260213.22 | U17: =1/(1+สมมติฐาน!$B$45)^(A17-1) -> 0.73069021 | V17: =S17*U17 -> 222773.75
A18: 10 | B18: =สมมติฐาน!$B$42+A18-1 -> 2578 | C18: =สมมติฐาน!$B$7+A18-1 -> 31 | D18: =IF(C18<สมมติฐาน!$B$8,"รับราชการ","รับบำนาญ") -> รับราชการ | E18: =(1+สมมติฐาน!$B$43)^(A18-1) -> 1.1950926 | F18: =IF(D18="รับราชการ",สมมติฐาน!$B$13*(1+สมมติฐาน!$B$15)^(A18-1)*E18,0) -> 20961.306 | G18: =F18*12 -> 251535.67 | H18: =IF(D18="รับราชการ",IF(A18>=สมมติฐาน!$B$19,สมมติฐาน!$B$18,IF(A18>=สมมติฐาน!$B$17,สมมติฐาน!$B$16,0))*12*E18,0) -> 0 | I18: =G18*สมมติฐาน!$B$21 -> 12576.783 | J18: =IF(AND(D18="รับราชการ",A18<=สมมติฐาน!$B$23),สมมติฐาน!$B$22*12*E18,0) -> 0 | K18: =IF(AND(D18="รับราชการ",A18>=สมมติฐาน!$B$27,A18<สมมติฐาน!$B$27+สมมติฐาน!$B$28),สมมติฐาน!$B$25*สมมติฐาน!$B$26*E18,0) -> 14341.111 | L18: =G18*สมมติฐาน!$B$20 -> 7546.0701 | M18: =IF(D18="รับราชการ",สมมติฐาน!$B$30+IF(AND(A18>=สมมติฐาน!$B$32,A18<=สมมติฐาน!$B$33),สมมติฐาน!$B$31,0),0) -> 2 | N18: =IF(AND(A18>=สมมติฐาน!$B$35,A18<=สมมติฐาน!$B$36),สมมติฐาน!$B$34,0)+IF(D18="รับราชการ",0,สมมติฐาน!$B$37) -> 1 | O18: =(1+สมมติฐาน!$B$43)^(A18-1)*(1+สมมติฐาน!$B$44)^(A18-1) -> 1.4282462 | P18: =(M18*สมมติฐาน!$B$38+N18*สมมติฐาน!$B$39)*O18 -> 58558.096 | Q18: =IF(D18="รับราชการ",0,$AB$6*12*(1+สมมติฐาน!$B$46)^(A18-38-1)) -> 0 | R18: =IF(C18=สมมติฐาน!$B$8,$AB$7,0)+IF(C18=65,$AB$9,0)+IF(A18=57,$AB$10+$AB$11,0) -> 0 | S18: =G18+H18+I18+J18+K18+L18+P18+Q18+R18 -> 344557.73 | T18: =S18/E18 -> 288310.49 | U18: =1/(1+สมมติฐาน!$B$45)^(A18-1) -> 0.70258674 | V18: =S18*U18 -> 242081.69
A19: 11 | B19: =สมมติฐาน!$B$42+A19-1 -> 2579 | C19: =สมมติฐาน!$B$7+A19-1 -> 32 | D19: =IF(C19<สมมติฐาน!$B$8,"รับราชการ","รับบำนาญ") -> รับราชการ | E19: =(1+สมมติฐาน!$B$43)^(A19-1) -> 1.2189944 | F19: =IF(D19="รับราชการ",สมมติฐาน!$B$13*(1+สมมติฐาน!$B$15)^(A19-1)*E19,0) -> 21936.714 | G19: =F19*12 -> 263240.56 | H19: =IF(D19="รับราชการ",IF(A19>=สมมติฐาน!$B$19,สมมติฐาน!$B$18,IF(A19>=สมมติฐาน!$B$17,สมมติฐาน!$B$16,0))*12*E19,0) -> 0 | I19: =G19*สมมติฐาน!$B$21 -> 13162.028 | J19: =IF(AND(D19="รับราชการ",A19<=สมมติฐาน!$B$23),สมมติฐาน!$B$22*12*E19,0) -> 0 | K19: =IF(AND(D19="รับราชการ",A19>=สมมติฐาน!$B$27,A19<สมมติฐาน!$B$27+สมมติฐาน!$B$28),สมมติฐาน!$B$25*สมมติฐาน!$B$26*E19,0) -> 14627.933 | L19: =G19*สมมติฐาน!$B$20 -> 7897.2169 | M19: =IF(D19="รับราชการ",สมมติฐาน!$B$30+IF(AND(A19>=สมมติฐาน!$B$32,A19<=สมมติฐาน!$B$33),สมมติฐาน!$B$31,0),0) -> 2 | N19: =IF(AND(A19>=สมมติฐาน!$B$35,A19<=สมมติฐาน!$B$36),สมมติฐาน!$B$34,0)+IF(D19="รับราชการ",0,สมมติฐาน!$B$37) -> 1 | O19: =(1+สมมติฐาน!$B$43)^(A19-1)*(1+สมมติฐาน!$B$44)^(A19-1) -> 1.4859474 | P19: =(M19*สมมติฐาน!$B$38+N19*สมมติฐาน!$B$39)*O19 -> 60923.843 | Q19: =IF(D19="รับราชการ",0,$AB$6*12*(1+สมมติฐาน!$B$46)^(A19-38-1)) -> 0 | R19: =IF(C19=สมมติฐาน!$B$8,$AB$7,0)+IF(C19=65,$AB$9,0)+IF(A19=57,$AB$10+$AB$11,0) -> 0 | S19: =G19+H19+I19+J19+K19+L19+P19+Q19+R19 -> 359851.58 | T19: =S19/E19 -> 295203.64 | U19: =1/(1+สมมติฐาน!$B$45)^(A19-1) -> 0.67556417 | V19: =S19*U19 -> 243102.84
A20: 12 | B20: =สมมติฐาน!$B$42+A20-1 -> 2580 | C20: =สมมติฐาน!$B$7+A20-1 -> 33 | D20: =IF(C20<สมมติฐาน!$B$8,"รับราชการ","รับบำนาญ") -> รับราชการ | E20: =(1+สมมติฐาน!$B$43)^(A20-1) -> 1.2433743 | F20: =IF(D20="รับราชการ",สมมติฐาน!$B$13*(1+สมมติฐาน!$B$15)^(A20-1)*E20,0) -> 22957.511 | G20: =F20*12 -> 275490.13 | H20: =IF(D20="รับราชการ",IF(A20>=สมมติฐาน!$B$19,สมมติฐาน!$B$18,IF(A20>=สมมติฐาน!$B$17,สมมติฐาน!$B$16,0))*12*E20,0) -> 0 | I20: =G20*สมมติฐาน!$B$21 -> 13774.507 | J20: =IF(AND(D20="รับราชการ",A20<=สมมติฐาน!$B$23),สมมติฐาน!$B$22*12*E20,0) -> 0 | K20: =IF(AND(D20="รับราชการ",A20>=สมมติฐาน!$B$27,A20<สมมติฐาน!$B$27+สมมติฐาน!$B$28),สมมติฐาน!$B$25*สมมติฐาน!$B$26*E20,0) -> 14920.492 | L20: =G20*สมมติฐาน!$B$20 -> 8264.7039 | M20: =IF(D20="รับราชการ",สมมติฐาน!$B$30+IF(AND(A20>=สมมติฐาน!$B$32,A20<=สมมติฐาน!$B$33),สมมติฐาน!$B$31,0),0) -> 2 | N20: =IF(AND(A20>=สมมติฐาน!$B$35,A20<=สมมติฐาน!$B$36),สมมติฐาน!$B$34,0)+IF(D20="รับราชการ",0,สมมติฐาน!$B$37) -> 1 | O20: =(1+สมมติฐาน!$B$43)^(A20-1)*(1+สมมติฐาน!$B$44)^(A20-1) -> 1.5459797 | P20: =(M20*สมมติฐาน!$B$38+N20*สมมติฐาน!$B$39)*O20 -> 63385.167 | Q20: =IF(D20="รับราชการ",0,$AB$6*12*(1+สมมติฐาน!$B$46)^(A20-38-1)) -> 0 | R20: =IF(C20=สมมติฐาน!$B$8,$AB$7,0)+IF(C20=65,$AB$9,0)+IF(A20=57,$AB$10+$AB$11,0) -> 0 | S20: =G20+H20+I20+J20+K20+L20+P20+Q20+R20 -> 375835 | T20: =S20/E20 -> 302270.2 | U20: =1/(1+สมมติฐาน!$B$45)^(A20-1) -> 0.64958093 | V20: =S20*U20 -> 244135.25
A21: 13 | B21: =สมมติฐาน!$B$42+A21-1 -> 2581 | C21: =สมมติฐาน!$B$7+A21-1 -> 34 | D21: =IF(C21<สมมติฐาน!$B$8,"รับราชการ","รับบำนาญ") -> รับราชการ | E21: =(1+สมมติฐาน!$B$43)^(A21-1) -> 1.2682418 | F21: =IF(D21="รับราชการ",สมมติฐาน!$B$13*(1+สมมติฐาน!$B$15)^(A21-1)*E21,0) -> 24025.81 | G21: =F21*12 -> 288309.72 | H21: =IF(D21="รับราชการ",IF(A21>=สมมติฐาน!$B$19,สมมติฐาน!$B$18,IF(A21>=สมมติฐาน!$B$17,สมมติฐาน!$B$16,0))*12*E21,0) -> 0 | I21: =G21*สมมติฐาน!$B$21 -> 14415.486 | J21: =IF(AND(D21="รับราชการ",A21<=สมมติฐาน!$B$23),สมมติฐาน!$B$22*12*E21,0) -> 0 | K21: =IF(AND(D21="รับราชการ",A21>=สมมติฐาน!$B$27,A21<สมมติฐาน!$B$27+สมมติฐาน!$B$28),สมมติฐาน!$B$25*สมมติฐาน!$B$26*E21,0) -> 15218.902 | L21: =G21*สมมติฐาน!$B$20 -> 8649.2915 | M21: =IF(D21="รับราชการ",สมมติฐาน!$B$30+IF(AND(A21>=สมมติฐาน!$B$32,A21<=สมมติฐาน!$B$33),สมมติฐาน!$B$31,0),0) -> 2 | N21: =IF(AND(A21>=สมมติฐาน!$B$35,A21<=สมมติฐาน!$B$36),สมมติฐาน!$B$34,0)+IF(D21="รับราชการ",0,สมมติฐาน!$B$37) -> 1 | O21: =(1+สมมติฐาน!$B$43)^(A21-1)*(1+สมมติฐาน!$B$44)^(A21-1) -> 1.6084372 | P21: =(M21*สมมติฐาน!$B$38+N21*สมมติฐาน!$B$39)*O21 -> 65945.927 | Q21: =IF(D21="รับราชการ",0,$AB$6*12*(1+สมมติฐาน!$B$46)^(A21-38-1)) -> 0 | R21: =IF(C21=สมมติฐาน!$B$8,$AB$7,0)+IF(C21=65,$AB$9,0)+IF(A21=57,$AB$10+$AB$11,0) -> 0 | S21: =G21+H21+I21+J21+K21+L21+P21+Q21+R21 -> 392539.32 | T21: =S21/E21 -> 309514.58 | U21: =1/(1+สมมติฐาน!$B$45)^(A21-1) -> 0.62459705 | V21: =S21*U21 -> 245178.9
A22: 14 | B22: =สมมติฐาน!$B$42+A22-1 -> 2582 | C22: =สมมติฐาน!$B$7+A22-1 -> 35 | D22: =IF(C22<สมมติฐาน!$B$8,"รับราชการ","รับบำนาญ") -> รับราชการ | E22: =(1+สมมติฐาน!$B$43)^(A22-1) -> 1.2936066 | F22: =IF(D22="รับราชการ",สมมติฐาน!$B$13*(1+สมมติฐาน!$B$15)^(A22-1)*E22,0) -> 25143.82 | G22: =F22*12 -> 301725.84 | H22: =IF(D22="รับราชการ",IF(A22>=สมมติฐาน!$B$19,สมมติฐาน!$B$18,IF(A22>=สมมติฐาน!$B$17,สมมติฐาน!$B$16,0))*12*E22,0) -> 0 | I22: =G22*สมมติฐาน!$B$21 -> 15086.292 | J22: =IF(AND(D22="รับราชการ",A22<=สมมติฐาน!$B$23),สมมติฐาน!$B$22*12*E22,0) -> 0 | K22: =IF(AND(D22="รับราชการ",A22>=สมมติฐาน!$B$27,A22<สมมติฐาน!$B$27+สมมติฐาน!$B$28),สมมติฐาน!$B$25*สมมติฐาน!$B$26*E22,0) -> 15523.28 | L22: =G22*สมมติฐาน!$B$20 -> 9051.7753 | M22: =IF(D22="รับราชการ",สมมติฐาน!$B$30+IF(AND(A22>=สมมติฐาน!$B$32,A22<=สมมติฐาน!$B$33),สมมติฐาน!$B$31,0),0) -> 2 | N22: =IF(AND(A22>=สมมติฐาน!$B$35,A22<=สมมติฐาน!$B$36),สมมติฐาน!$B$34,0)+IF(D22="รับราชการ",0,สมมติฐาน!$B$37) -> 1 | O22: =(1+สมมติฐาน!$B$43)^(A22-1)*(1+สมมติฐาน!$B$44)^(A22-1) -> 1.6734181 | P22: =(M22*สมมติฐาน!$B$38+N22*สมมติฐาน!$B$39)*O22 -> 68610.143 | Q22: =IF(D22="รับราชการ",0,$AB$6*12*(1+สมมติฐาน!$B$46)^(A22-38-1)) -> 0 | R22: =IF(C22=สมมติฐาน!$B$8,$AB$7,0)+IF(C22=65,$AB$9,0)+IF(A22=57,$AB$10+$AB$11,0) -> 0 | S22: =G22+H22+I22+J22+K22+L22+P22+Q22+R22 -> 409997.33 | T22: =S22/E22 -> 316941.27 | U22: =1/(1+สมมติฐาน!$B$45)^(A22-1) -> 0.60057409 | V22: =S22*U22 -> 246233.77
A23: 15 | B23: =สมมติฐาน!$B$42+A23-1 -> 2583 | C23: =สมมติฐาน!$B$7+A23-1 -> 36 | D23: =IF(C23<สมมติฐาน!$B$8,"รับราชการ","รับบำนาญ") -> รับราชการ | E23: =(1+สมมติฐาน!$B$43)^(A23-1) -> 1.3194788 | F23: =IF(D23="รับราชการ",สมมติฐาน!$B$13*(1+สมมติฐาน!$B$15)^(A23-1)*E23,0) -> 26313.856 | G23: =F23*12 -> 315766.27 | H23: =IF(D23="รับราชการ",IF(A23>=สมมติฐาน!$B$19,สมมติฐาน!$B$18,IF(A23>=สมมติฐาน!$B$17,สมมติฐาน!$B$16,0))*12*E23,0) -> 0 | I23: =G23*สมมติฐาน!$B$21 -> 15788.314 | J23: =IF(AND(D23="รับราชการ",A23<=สมมติฐาน!$B$23),สมมติฐาน!$B$22*12*E23,0) -> 0 | K23: =IF(AND(D23="รับราชการ",A23>=สมมติฐาน!$B$27,A23<สมมติฐาน!$B$27+สมมติฐาน!$B$28),สมมติฐาน!$B$25*สมมติฐาน!$B$26*E23,0) -> 15833.745 | L23: =G23*สมมติฐาน!$B$20 -> 9472.9882 | M23: =IF(D23="รับราชการ",สมมติฐาน!$B$30+IF(AND(A23>=สมมติฐาน!$B$32,A23<=สมมติฐาน!$B$33),สมมติฐาน!$B$31,0),0) -> 2 | N23: =IF(AND(A23>=สมมติฐาน!$B$35,A23<=สมมติฐาน!$B$36),สมมติฐาน!$B$34,0)+IF(D23="รับราชการ",0,สมมติฐาน!$B$37) -> 1 | O23: =(1+สมมติฐาน!$B$43)^(A23-1)*(1+สมมติฐาน!$B$44)^(A23-1) -> 1.7410242 | P23: =(M23*สมมติฐาน!$B$38+N23*สมมติฐาน!$B$39)*O23 -> 71381.992 | Q23: =IF(D23="รับราชการ",0,$AB$6*12*(1+สมมติฐาน!$B$46)^(A23-38-1)) -> 0 | R23: =IF(C23=สมมติฐาน!$B$8,$AB$7,0)+IF(C23=65,$AB$9,0)+IF(A23=57,$AB$10+$AB$11,0) -> 0 | S23: =G23+H23+I23+J23+K23+L23+P23+Q23+R23 -> 428243.31 | T23: =S23/E23 -> 324554.91 | U23: =1/(1+สมมติฐาน!$B$45)^(A23-1) -> 0.57747508 | V23: =S23*U23 -> 247299.84
... A65: 57 | B65: =สมมติฐาน!$B$42+A65-1 -> 2625 | C65: =สมมติฐาน!$B$7+A65-1 -> 78 | D65: =IF(C65<สมมติฐาน!$B$8,"รับราชการ","รับบำนาญ") -> รับบำนาญ | E65: =(1+สมมติฐาน!$B$43)^(A65-1) -> 3.0311653 | F65: =IF(D65="รับราชการ",สมมติฐาน!$B$13*(1+สมมติฐาน!$B$15)^(A65-1)*E65,0) -> 0 | G65: =F65*12 -> 0 | H65: =IF(D65="รับราชการ",IF(A65>=สมมติฐาน!$B$19,สมมติฐาน!$B$18,IF(A65>=สมมติฐาน!$B$17,สมมติฐาน!$B$16,0))*12*E65,0) -> 0 | I65: =G65*สมมติฐาน!$B$21 -> 0 | J65: =IF(AND(D65="รับราชการ",A65<=สมมติฐาน!$B$23),สมมติฐาน!$B$22*12*E65,0) -> 0 | K65: =IF(AND(D65="รับราชการ",A65>=สมมติฐาน!$B$27,A65<สมมติฐาน!$B$27+สมมติฐาน!$B$28),สมมติฐาน!$B$25*สมมติฐาน!$B$26*E65,0) -> 0 | L65: =G65*สมมติฐาน!$B$20 -> 0 | M65: =IF(D65="รับราชการ",สมมติฐาน!$B$30+IF(AND(A65>=สมมติฐาน!$B$32,A65<=สมมติฐาน!$B$33),สมมติฐาน!$B$31,0),0) -> 0 | N65: =IF(AND(A65>=สมมติฐาน!$B$35,A65<=สมมติฐาน!$B$36),สมมติฐาน!$B$34,0)+IF(D65="รับราชการ",0,สมมติฐาน!$B$37) -> 1 | O65: =(1+สมมติฐาน!$B$43)^(A65-1)*(1+สมมติฐาน!$B$44)^(A65-1) -> 9.187963 | P65: =(M65*สมมติฐาน!$B$38+N65*สมมติฐาน!$B$39)*O65 -> 229699.07 | Q65: =IF(D65="รับราชการ",0,$AB$6*12*(1+สมมติฐาน!$B$46)^(A65-38-1)) -> 575678.12 | R65: =IF(C65=สมมติฐาน!$B$8,$AB$7,0)+IF(C65=65,$AB$9,0)+IF(A65=57,$AB$10+$AB$11,0) -> 1083114.8 | S65: =G65+H65+I65+J65+K65+L65+P65+Q65+R65 -> 1888492 | T65: =S65/E65 -> 623025.08 | U65: =1/(1+สมมติฐาน!$B$45)^(A65-1) -> 0.11120722 | V65: =S65*U65 -> 210013.95
A66: รวม | G66: =SUM(G9:G65) -> 16625424 | H66: =SUM(H9:H65) -> 0 | I66: =SUM(I9:I65) -> 831271.19 | J66: =SUM(J9:J65) -> 0 | K66: =SUM(K9:K65) -> 248006.81 | L66: =SUM(L9:L65) -> 498762.71 | P66: =SUM(P9:P65) -> 4911196.7 | Q66: =SUM(Q9:Q65) -> 10937884 | R66: =SUM(R9:R65) -> 1583114.8 | S66: =SUM(S9:S65) -> 35635660 | T66: =SUM(T9:T65) -> 19064877 | V66: =SUM(V9:V65) -> 11293360

Sheet 2_กลาง
A1: กรณี กลาง — ข้าราชการวิชาการ — เกษียณระดับชำนาญการพิเศษ มีคู่สมรส บุตร 2 บิดามารดา 2
A2: ทุกจำนวนเงินเป็น 'ตัวเงินจริง ณ ปีนั้น' (nominal) เว้นคอลัมน์ที่ระบุไว้ • แก้สมมติฐานได้ที่แผ่น 'สมมติฐาน' เท่านั้น • ตัวแปรบำนาญคำนวณไว้ทางขวามือ | Y2: ตัวแปรบำนาญ (คำนวณจากตารางด้านล่าง)
Y3: เงินเดือนเฉลี่ย 60 เดือนสุดท้าย | AB3: =AVERAGE(F39:F43) -> 92369.967
Y4: บำนาญรายเดือน | AB4: =MIN(AB3*สมมติฐาน!$C$10/สมมติฐาน!$B$48,AB3*สมมติฐาน!$B$47) -> 64658.977
Y5: ช.ค.บ. รายเดือน | AB5: =MAX(0,สมมติฐาน!$B$49-AB4) -> 0
Y6: บำนาญ + ช.ค.บ. รายเดือน | AB6: =AB4+AB5 -> 64658.977
Y7: บำเหน็จดำรงชีพ ครั้งที่ 1 (ปีเกษียณ) | AB7: =MIN(AB4*สมมติฐาน!$B$52,สมมติฐาน!$B$50) -> 200000
A8: ปีที่ | B8: ปี พ.ศ. | C8: อายุ | D8: สถานะ | E8: ดัชนีราคา | F8: เงินเดือน (บาท/เดือน) | G8: เงินเดือน รายปี | H8: เงินประจำตำแหน่ง + ค่าตอบแทน | I8: เงินสมทบ กบข. (รัฐจ่าย) | J8: ค่าเช่าบ้าน | K8: ค่าการศึกษา บุตร | L8: ค่าตอบแทน/ สวัสดิการอื่น | M8: ผู้ใช้สิทธิ ไม่สูงอายุ | N8: ผู้ใช้สิทธิ สูงอายุ | O8: ดัชนี ค่ารักษา | P8: ค่ารักษาพยาบาล | Q8: บำนาญ + ช.ค.บ. | R8: เงินก้อน (ดำรงชีพ/ตกทอด/ค่าทำศพ) | S8: รวมต้นทุนปีนั้น (ตัวเงินจริง) | T8: รวม ณ ราคาปี 2569 | U8: ตัวคิดลด | V8: มูลค่าปัจจุบัน | Y8: บำเหน็จดำรงชีพ รวมทั้งหมด | AB8: =MIN(AB4*สมมติฐาน!$B$52,สมมติฐาน!$B$51) -> 500000
A9: 1 | B9: =สมมติฐาน!$B$42+A9-1 -> 2569 | C9: =สมมติฐาน!$C$7+A9-1 -> 25 | D9: =IF(C9<สมมติฐาน!$C$8,"รับราชการ","รับบำนาญ") -> รับราชการ | E9: =(1+สมมติฐาน!$B$43)^(A9-1) -> 1 | F9: =IF(D9="รับราชการ",สมมติฐาน!$C$13*(1+สมมติฐาน!$C$15)^(A9-1)*E9,0) -> 18220 | G9: =F9*12 -> 218640 | H9: =IF(D9="รับราชการ",IF(A9>=สมมติฐาน!$C$19,สมมติฐาน!$C$18,IF(A9>=สมมติฐาน!$C$17,สมมติฐาน!$C$16,0))*12*E9,0) -> 0 | I9: =G9*สมมติฐาน!$C$21 -> 10932 | J9: =IF(AND(D9="รับราชการ",A9<=สมมติฐาน!$C$23),สมมติฐาน!$C$22*12*E9,0) -> 48000 | K9: =IF(AND(D9="รับราชการ",A9>=สมมติฐาน!$C$27,A9<สมมติฐาน!$C$27+สมมติฐาน!$C$28),สมมติฐาน!$C$25*สมมติฐาน!$C$26*E9,0) -> 0 | L9: =G9*สมมติฐาน!$C$20 -> 6559.2 | M9: =IF(D9="รับราชการ",สมมติฐาน!$C$30+IF(AND(A9>=สมมติฐาน!$C$32,A9<=สมมติฐาน!$C$33),สมมติฐาน!$C$31,0),0) -> 2 | N9: =IF(AND(A9>=สมมติฐาน!$C$35,A9<=สมมติฐาน!$C$36),สมมติฐาน!$C$34,0)+IF(D9="รับราชการ",0,สมมติฐาน!$C$37) -> 2 | O9: =(1+สมมติฐาน!$B$43)^(A9-1)*(1+สมมติฐาน!$B$44)^(A9-1) -> 1 | P9: =(M9*สมมติฐาน!$C$38+N9*สมมติฐาน!$C$39)*O9 -> 66000 | Q9: =IF(D9="รับราชการ",0,$AB$6*12*(1+สมมติฐาน!$B$46)^(A9-35-1)) -> 0 | R9: =IF(C9=สมมติฐาน!$C$8,$AB$7,0)+IF(C9=65,$AB$9,0)+IF(A9=58,$AB$10+$AB$11,0) -> 0 | S9: =G9+H9+I9+J9+K9+L9+P9+Q9+R9 -> 350131.2 | T9: =S9/E9 -> 350131.2 | U9: =1/(1+สมมติฐาน!$B$45)^(A9-1) -> 1 | V9: =S9*U9 -> 350131.2 | Y9: บำเหน็จดำรงชีพ ครั้งที่ 2 (อายุ 65) | AB9: =AB8-AB7 -> 300000
A10: 2 | B10: =สมมติฐาน!$B$42+A10-1 -> 2570 | C10: =สมมติฐาน!$C$7+A10-1 -> 26 | D10: =IF(C10<สมมติฐาน!$C$8,"รับราชการ","รับบำนาญ") -> รับราชการ | E10: =(1+สมมติฐาน!$B$43)^(A10-1) -> 1.02 | F10: =IF(D10="รับราชการ",สมมติฐาน!$C$13*(1+สมมติฐาน!$C$15)^(A10-1)*E10,0) -> 19166.565 | G10: =F10*12 -> 229998.78 | H10: =IF(D10="รับราชการ",IF(A10>=สมมติฐาน!$C$19,สมมติฐาน!$C$18,IF(A10>=สมมติฐาน!$C$17,สมมติฐาน!$C$16,0))*12*E10,0) -> 0 | I10: =G10*สมมติฐาน!$C$21 -> 11499.939 | J10: =IF(AND(D10="รับราชการ",A10<=สมมติฐาน!$C$23),สมมติฐาน!$C$22*12*E10,0) -> 48960 | K10: =IF(AND(D10="รับราชการ",A10>=สมมติฐาน!$C$27,A10<สมมติฐาน!$C$27+สมมติฐาน!$C$28),สมมติฐาน!$C$25*สมมติฐาน!$C$26*E10,0) -> 0 | L10: =G10*สมมติฐาน!$C$20 -> 6899.9633 | M10: =IF(D10="รับราชการ",สมมติฐาน!$C$30+IF(AND(A10>=สมมติฐาน!$C$32,A10<=สมมติฐาน!$C$33),สมมติฐาน!$C$31,0),0) -> 2 | N10: =IF(AND(A10>=สมมติฐาน!$C$35,A10<=สมมติฐาน!$C$36),สมมติฐาน!$C$34,0)+IF(D10="รับราชการ",0,สมมติฐาน!$C$37) -> 2 | O10: =(1+สมมติฐาน!$B$43)^(A10-1)*(1+สมมติฐาน!$B$44)^(A10-1) -> 1.0404 | P10: =(M10*สมมติฐาน!$C$38+N10*สมมติฐาน!$C$39)*O10 -> 68666.4 | Q10: =IF(D10="รับราชการ",0,$AB$6*12*(1+สมมติฐาน!$B$46)^(A10-35-1)) -> 0 | R10: =IF(C10=สมมติฐาน!$C$8,$AB$7,0)+IF(C10=65,$AB$9,0)+IF(A10=58,$AB$10+$AB$11,0) -> 0 | S10: =G10+H10+I10+J10+K10+L10+P10+Q10+R10 -> 366025.08 | T10: =S10/E10 -> 358848.12 | U10: =1/(1+สมมติฐาน!$B$45)^(A10-1) -> 0.96153846 | V10: =S10*U10 -> 351947.19 | Y10: บำเหน็จตกทอด (ปีเสียชีวิต) | AB10: =MAX(0,AB6*สมมติฐาน!$B$53-AB8) -> 1439769.3
A11: 3 | B11: =สมมติฐาน!$B$42+A11-1 -> 2571 | C11: =สมมติฐาน!$C$7+A11-1 -> 27 | D11: =IF(C11<สมมติฐาน!$C$8,"รับราชการ","รับบำนาญ") -> รับราชการ | E11: =(1+สมมติฐาน!$B$43)^(A11-1) -> 1.0404 | F11: =IF(D11="รับราชการ",สมมติฐาน!$C$13*(1+สมมติฐาน!$C$15)^(A11-1)*E11,0) -> 20162.305 | G11: =F11*12 -> 241947.66 | H11: =IF(D11="รับราชการ",IF(A11>=สมมติฐาน!$C$19,สมมติฐาน!$C$18,IF(A11>=สมมติฐาน!$C$17,สมมติฐาน!$C$16,0))*12*E11,0) -> 0 | I11: =G11*สมมติฐาน!$C$21 -> 12097.383 | J11: =IF(AND(D11="รับราชการ",A11<=สมมติฐาน!$C$23),สมมติฐาน!$C$22*12*E11,0) -> 49939.2 | K11: =IF(AND(D11="รับราชการ",A11>=สมมติฐาน!$C$27,A11<สมมติฐาน!$C$27+สมมติฐาน!$C$28),สมมติฐาน!$C$25*สมมติฐาน!$C$26*E11,0) -> 0 | L11: =G11*สมมติฐาน!$C$20 -> 7258.4299 | M11: =IF(D11="รับราชการ",สมมติฐาน!$C$30+IF(AND(A11>=สมมติฐาน!$C$32,A11<=สมมติฐาน!$C$33),สมมติฐาน!$C$31,0),0) -> 2 | N11: =IF(AND(A11>=สมมติฐาน!$C$35,A11<=สมมติฐาน!$C$36),สมมติฐาน!$C$34,0)+IF(D11="รับราชการ",0,สมมติฐาน!$C$37) -> 2 | O11: =(1+สมมติฐาน!$B$43)^(A11-1)*(1+สมมติฐาน!$B$44)^(A11-1) -> 1.0824322 | P11: =(M11*สมมติฐาน!$C$38+N11*สมมติฐาน!$C$39)*O11 -> 71440.523 | Q11: =IF(D11="รับราชการ",0,$AB$6*12*(1+สมมติฐาน!$B$46)^(A11-35-1)) -> 0 | R11: =IF(C11=สมมติฐาน!$C$8,$AB$7,0)+IF(C11=65,$AB$9,0)+IF(A11=58,$AB$10+$AB$11,0) -> 0 | S11: =G11+H11+I11+J11+K11+L11+P11+Q11+R11 -> 382683.2 | T11: =S11/E11 -> 367823.14 | U11: =1/(1+สมมติฐาน!$B$45)^(A11-1) -> 0.92455621 | V11: =S11*U11 -> 353812.13 | Y11: เงินช่วยพิเศษ ค่าทำศพ (ปีเสียชีวิต) | AB11: =AB6*สมมติฐาน!$B$54 -> 193976.93
A12: 4 | B12: =สมมติฐาน!$B$42+A12-1 -> 2572 | C12: =สมมติฐาน!$C$7+A12-1 -> 28 | D12: =IF(C12<สมมติฐาน!$C$8,"รับราชการ","รับบำนาญ") -> รับราชการ | E12: =(1+สมมติฐาน!$B$43)^(A12-1) -> 1.061208 | F12: =IF(D12="รับราชการ",สมมติฐาน!$C$13*(1+สมมติฐาน!$C$15)^(A12-1)*E12,0) -> 21209.776 | G12: =F12*12 -> 254517.32 | H12: =IF(D12="รับราชการ",IF(A12>=สมมติฐาน!$C$19,สมมติฐาน!$C$18,IF(A12>=สมมติฐาน!$C$17,สมมติฐาน!$C$16,0))*12*E12,0) -> 0 | I12: =G12*สมมติฐาน!$C$21 -> 12725.866 | J12: =IF(AND(D12="รับราชการ",A12<=สมมติฐาน!$C$23),สมมติฐาน!$C$22*12*E12,0) -> 50937.984 | K12: =IF(AND(D12="รับราชการ",A12>=สมมติฐาน!$C$27,A12<สมมติฐาน!$C$27+สมมติฐาน!$C$28),สมมติฐาน!$C$25*สมมติฐาน!$C$26*E12,0) -> 0 | L12: =G12*สมมติฐาน!$C$20 -> 7635.5195 | M12: =IF(D12="รับราชการ",สมมติฐาน!$C$30+IF(AND(A12>=สมมติฐาน!$C$32,A12<=สมมติฐาน!$C$33),สมมติฐาน!$C$31,0),0) -> 2 | N12: =IF(AND(A12>=สมมติฐาน!$C$35,A12<=สมมติฐาน!$C$36),สมมติฐาน!$C$34,0)+IF(D12="รับราชการ",0,สมมติฐาน!$C$37) -> 2 | O12: =(1+สมมติฐาน!$B$43)^(A12-1)*(1+สมมติฐาน!$B$44)^(A12-1) -> 1.1261624 | P12: =(M12*สมมติฐาน!$C$38+N12*สมมติฐาน!$C$39)*O12 -> 74326.72 | Q12: =IF(D12="รับราชการ",0,$AB$6*12*(1+สมมติฐาน!$B$46)^(A12-35-1)) -> 0 | R12: =IF(C12=สมมติฐาน!$C$8,$AB$7,0)+IF(C12=65,$AB$9,0)+IF(A12=58,$AB$10+$AB$11,0) -> 0 | S12: =G12+H12+I12+J12+K12+L12+P12+Q12+R12 -> 400143.41 | T12: =S12/E12 -> 377064.07 | U12: =1/(1+สมมติฐาน!$B$45)^(A12-1) -> 0.88899636 | V12: =S12*U12 -> 355726.03
A13: 5 | B13: =สมมติฐาน!$B$42+A13-1 -> 2573 | C13: =สมมติฐาน!$C$7+A13-1 -> 29 | D13: =IF(C13<สมมติฐาน!$C$8,"รับราชการ","รับบำนาญ") -> รับราชการ | E13: =(1+สมมติฐาน!$B$43)^(A13-1) -> 1.0824322 | F13: =IF(D13="รับราชการ",สมมติฐาน!$C$13*(1+สมมติฐาน!$C$15)^(A13-1)*E13,0) -> 22311.666 | G13: =F13*12 -> 267739.99 | H13: =IF(D13="รับราชการ",IF(A13>=สมมติฐาน!$C$19,สมมติฐาน!$C$18,IF(A13>=สมมติฐาน!$C$17,สมมติฐาน!$C$16,0))*12*E13,0) -> 0 | I13: =G13*สมมติฐาน!$C$21 -> 13387 | J13: =IF(AND(D13="รับราชการ",A13<=สมมติฐาน!$C$23),สมมติฐาน!$C$22*12*E13,0) -> 51956.744 | K13: =IF(AND(D13="รับราชการ",A13>=สมมติฐาน!$C$27,A13<สมมติฐาน!$C$27+สมมติฐาน!$C$28),สมมติฐาน!$C$25*สมมติฐาน!$C$26*E13,0) -> 0 | L13: =G13*สมมติฐาน!$C$20 -> 8032.1997 | M13: =IF(D13="รับราชการ",สมมติฐาน!$C$30+IF(AND(A13>=สมมติฐาน!$C$32,A13<=สมมติฐาน!$C$33),สมมติฐาน!$C$31,0),0) -> 2 | N13: =IF(AND(A13>=สมมติฐาน!$C$35,A13<=สมมติฐาน!$C$36),สมมติฐาน!$C$34,0)+IF(D13="รับราชการ",0,สมมติฐาน!$C$37) -> 2 | O13: =(1+สมมติฐาน!$B$43)^(A13-1)*(1+สมมติฐาน!$B$44)^(A13-1) -> 1.1716594 | P13: =(M13*สมมติฐาน!$C$38+N13*สมมติฐาน!$C$39)*O13 -> 77329.519 | Q13: =IF(D13="รับราชการ",0,$AB$6*12*(1+สมมติฐาน!$B$46)^(A13-35-1)) -> 0 | R13: =IF(C13=สมมติฐาน!$C$8,$AB$7,0)+IF(C13=65,$AB$9,0)+IF(A13=58,$AB$10+$AB$11,0) -> 0 | S13: =G13+H13+I13+J13+K13+L13+P13+Q13+R13 -> 418445.45 | T13: =S13/E13 -> 386578.92 | U13: =1/(1+สมมติฐาน!$B$45)^(A13-1) -> 0.85480419 | V13: =S13*U13 -> 357688.93
A14: 6 | B14: =สมมติฐาน!$B$42+A14-1 -> 2574 | C14: =สมมติฐาน!$C$7+A14-1 -> 30 | D14: =IF(C14<สมมติฐาน!$C$8,"รับราชการ","รับบำนาญ") -> รับราชการ | E14: =(1+สมมติฐาน!$B$43)^(A14-1) -> 1.1040808 | F14: =IF(D14="รับราชการ",สมมติฐาน!$C$13*(1+สมมติฐาน!$C$15)^(A14-1)*E14,0) -> 23470.801 | G14: =F14*12 -> 281649.61 | H14: =IF(D14="รับราชการ",IF(A14>=สมมติฐาน!$C$19,สมมติฐาน!$C$18,IF(A14>=สมมติฐาน!$C$17,สมมติฐาน!$C$16,0))*12*E14,0) -> 0 | I14: =G14*สมมติฐาน!$C$21 -> 14082.48 | J14: =IF(AND(D14="รับราชการ",A14<=สมมติฐาน!$C$23),สมมติฐาน!$C$22*12*E14,0) -> 52995.879 | K14: =IF(AND(D14="รับราชการ",A14>=สมมติฐาน!$C$27,A14<สมมติฐาน!$C$27+สมมติฐาน!$C$28),สมมติฐาน!$C$25*สมมติฐาน!$C$26*E14,0) -> 0 | L14: =G14*สมมติฐาน!$C$20 -> 8449.4882 | M14: =IF(D14="รับราชการ",สมมติฐาน!$C$30+IF(AND(A14>=สมมติฐาน!$C$32,A14<=สมมติฐาน!$C$33),สมมติฐาน!$C$31,0),0) -> 2 | N14: =IF(AND(A14>=สมมติฐาน!$C$35,A14<=สมมติฐาน!$C$36),สมมติฐาน!$C$34,0)+IF(D14="รับราชการ",0,สมมติฐาน!$C$37) -> 2 | O14: =(1+สมมติฐาน!$B$43)^(A14-1)*(1+สมมติฐาน!$B$44)^(A14-1) -> 1.2189944 | P14: =(M14*สมมติฐาน!$C$38+N14*สมมติฐาน!$C$39)*O14 -> 80453.632 | Q14: =IF(D14="รับราชการ",0,$AB$6*12*(1+สมมติฐาน!$B$46)^(A14-35-1)) -> 0 | R14: =IF(C14=สมมติฐาน!$C$8,$AB$7,0)+IF(C14=65,$AB$9,0)+IF(A14=58,$AB$10+$AB$11,0) -> 0 | S14: =G14+H14+I14+J14+K14+L14+P14+Q14+R14 -> 437631.09 | T14: =S14/E14 -> 396375.96 | U14: =1/(1+สมมติฐาน!$B$45)^(A14-1) -> 0.82192711 | V14: =S14*U14 -> 359700.85
A15: 7 | B15: =สมมติฐาน!$B$42+A15-1 -> 2575 | C15: =สมมติฐาน!$C$7+A15-1 -> 31 | D15: =IF(C15<สมมติฐาน!$C$8,"รับราชการ","รับบำนาญ") -> รับราชการ | E15: =(1+สมมติฐาน!$B$43)^(A15-1) -> 1.1261624 | F15: =IF(D15="รับราชการ",สมมติฐาน!$C$13*(1+สมมติฐาน!$C$15)^(A15-1)*E15,0) -> 24690.155 | G15: =F15*12 -> 296281.86 | H15: =IF(D15="รับราชการ",IF(A15>=สมมติฐาน!$C$19,สมมติฐาน!$C$18,IF(A15>=สมมติฐาน!$C$17,สมมติฐาน!$C$16,0))*12*E15,0) -> 0 | I15: =G15*สมมติฐาน!$C$21 -> 14814.093 | J15: =IF(AND(D15="รับราชการ",A15<=สมมติฐาน!$C$23),สมมติฐาน!$C$22*12*E15,0) -> 54055.796 | K15: =IF(AND(D15="รับราชการ",A15>=สมมติฐาน!$C$27,A15<สมมติฐาน!$C$27+สมมติฐาน!$C$28),สมมติฐาน!$C$25*สมมติฐาน!$C$26*E15,0) -> 0 | L15: =G15*สมมติฐาน!$C$20 -> 8888.4557 | M15: =IF(D15="รับราชการ",สมมติฐาน!$C$30+IF(AND(A15>=สมมติฐาน!$C$32,A15<=สมมติฐาน!$C$33),สมมติฐาน!$C$31,0),0) -> 2 | N15: =IF(AND(A15>=สมมติฐาน!$C$35,A15<=สมมติฐาน!$C$36),สมมติฐาน!$C$34,0)+IF(D15="รับราชการ",0,สมมติฐาน!$C$37) -> 2 | O15: =(1+สมมติฐาน!$B$43)^(A15-1)*(1+สมมติฐาน!$B$44)^(A15-1) -> 1.2682418 | P15: =(M15*สมมติฐาน!$C$38+N15*สมมติฐาน!$C$39)*O15 -> 83703.958 | Q15: =IF(D15="รับราชการ",0,$AB$6*12*(1+สมมติฐาน!$B$46)^(A15-35-1)) -> 0 | R15: =IF(C15=สมมติฐาน!$C$8,$AB$7,0)+IF(C15=65,$AB$9,0)+IF(A15=58,$AB$10+$AB$11,0) -> 0 | S15: =G15+H15+I15+J15+K15+L15+P15+Q15+R15 -> 457744.16 | T15: =S15/E15 -> 406463.71 | U15: =1/(1+สมมติฐาน!$B$45)^(A15-1) -> 0.79031453 | V15: =S15*U15 -> 361761.86
A16: 8 | B16: =สมมติฐาน!$B$42+A16-1 -> 2576 | C16: =สมมติฐาน!$C$7+A16-1 -> 32 | D16: =IF(C16<สมมติฐาน!$C$8,"รับราชการ","รับบำนาญ") -> รับราชการ | E16: =(1+สมมติฐาน!$B$43)^(A16-1) -> 1.1486857 | F16: =IF(D16="รับราชการ",สมมติฐาน!$C$13*(1+สมมติฐาน!$C$15)^(A16-1)*E16,0) -> 25972.857 | G16: =F16*12 -> 311674.28 | H16: =IF(D16="รับราชการ",IF(A16>=สมมติฐาน!$C$19,สมมติฐาน!$C$18,IF(A16>=สมมติฐาน!$C$17,สมมติฐาน!$C$16,0))*12*E16,0) -> 48244.798 | I16: =G16*สมมติฐาน!$C$21 -> 15583.714 | J16: =IF(AND(D16="รับราชการ",A16<=สมมติฐาน!$C$23),สมมติฐาน!$C$22*12*E16,0) -> 55136.912 | K16: =IF(AND(D16="รับราชการ",A16>=สมมติฐาน!$C$27,A16<สมมติฐาน!$C$27+สมมติฐาน!$C$28),สมมติฐาน!$C$25*สมมติฐาน!$C$26*E16,0) -> 57434.283 | L16: =G16*สมมติฐาน!$C$20 -> 9350.2283 | M16: =IF(D16="รับราชการ",สมมติฐาน!$C$30+IF(AND(A16>=สมมติฐาน!$C$32,A16<=สมมติฐาน!$C$33),สมมติฐาน!$C$31,0),0) -> 4 | N16: =IF(AND(A16>=สมมติฐาน!$C$35,A16<=สมมติฐาน!$C$36),สมมติฐาน!$C$34,0)+IF(D16="รับราชการ",0,สมมติฐาน!$C$37) -> 2 | O16: =(1+สมมติฐาน!$B$43)^(A16-1)*(1+สมมติฐาน!$B$44)^(A16-1) -> 1.3194788 | P16: =(M16*สมมติฐาน!$C$38+N16*สมมติฐาน!$C$39)*O16 -> 108197.26 | Q16: =IF(D16="รับราชการ",0,$AB$6*12*(1+สมมติฐาน!$B$46)^(A16-35-1)) -> 0 | R16: =IF(C16=สมมติฐาน!$C$8,$AB$7,0)+IF(C16=65,$AB$9,0)+IF(A16=58,$AB$10+$AB$11,0) -> 0 | S16: =G16+H16+I16+J16+K16+L16+P16+Q16+R16 -> 605621.47 | T16: =S16/E16 -> 527229.94 | U16: =1/(1+สมมติฐาน!$B$45)^(A16-1) -> 0.75991781 | V16: =S16*U16 -> 460222.54
A17: 9 | B17: =สมมติฐาน!$B$42+A17-1 -> 2577 | C17: =สมมติฐาน!$C$7+A17-1 -> 33 | D17: =IF(C17<สมมติฐาน!$C$8,"รับราชการ","รับบำนาญ") -> รับราชการ | E17: =(1+สมมติฐาน!$B$43)^(A17-1) -> 1.1716594 | F17: =IF(D17="รับราชการ",สมมติฐาน!$C$13*(1+สมมติฐาน!$C$15)^(A17-1)*E17,0) -> 27322.197 | G17: =F17*12 -> 327866.37 | H17: =IF(D17="รับราชการ",IF(A17>=สมมติฐาน!$C$19,สมมติฐาน!$C$18,IF(A17>=สมมติฐาน!$C$17,สมมติฐาน!$C$16,0))*12*E17,0) -> 49209.694 | I17: =G17*สมมติฐาน!$C$21 -> 16393.318 | J17: =IF(AND(D17="รับราชการ",A17<=สมมติฐาน!$C$23),สมมติฐาน!$C$22*12*E17,0) -> 56239.65 | K17: =IF(AND(D17="รับราชการ",A17>=สมมติฐาน!$C$27,A17<สมมติฐาน!$C$27+สมมติฐาน!$C$28),สมมติฐาน!$C$25*สมมติฐาน!$C$26*E17,0) -> 58582.969 | L17: =G17*สมมติฐาน!$C$20 -> 9835.991 | M17: =IF(D17="รับราชการ",สมมติฐาน!$C$30+IF(AND(A17>=สมมติฐาน!$C$32,A17<=สมมติฐาน!$C$33),สมมติฐาน!$C$31,0),0) -> 4 | N17: =IF(AND(A17>=สมมติฐาน!$C$35,A17<=สมมติฐาน!$C$36),สมมติฐาน!$C$34,0)+IF(D17="รับราชการ",0,สมมติฐาน!$C$37) -> 2 | O17: =(1+สมมติฐาน!$B$43)^(A17-1)*(1+สมมติฐาน!$B$44)^(A17-1) -> 1.3727857 | P17: =(M17*สมมติฐาน!$C$38+N17*สมมติฐาน!$C$39)*O17 -> 112568.43 | Q17: =IF(D17="รับราชการ",0,$AB$6*12*(1+สมมติฐาน!$B$46)^(A17-35-1)) -> 0 | R17: =IF(C17=สมมติฐาน!$C$8,$AB$7,0)+IF(C17=65,$AB$9,0)+IF(A17=58,$AB$10+$AB$11,0) -> 0 | S17: =G17+H17+I17+J17+K17+L17+P17+Q17+R17 -> 630696.42 | T17: =S17/E17 -> 538293.32 | U17: =1/(1+สมมติฐาน!$B$45)^(A17-1) -> 0.73069021 | V17: =S17*U17 -> 460843.69
A18: 10 | B18: =สมมติฐาน!$B$42+A18-1 -> 2578 | C18: =สมมติฐาน!$C$7+A18-1 -> 34 | D18: =IF(C18<สมมติฐาน!$C$8,"รับราชการ","รับบำนาญ") -> รับราชการ | E18: =(1+สมมติฐาน!$B$43)^(A18-1) -> 1.1950926 | F18: =IF(D18="รับราชการ",สมมติฐาน!$C$13*(1+สมมติฐาน!$C$15)^(A18-1)*E18,0) -> 28741.639 | G18: =F18*12 -> 344899.67 | H18: =IF(D18="รับราชการ",IF(A18>=สมมติฐาน!$C$19,สมมติฐาน!$C$18,IF(A18>=สมมติฐาน!$C$17,สมมติฐาน!$C$16,0))*12*E18,0) -> 50193.888 | I18: =G18*สมมติฐาน!$C$21 -> 17244.983 | J18: =IF(AND(D18="รับราชการ",A18<=สมมติฐาน!$C$23),สมมติฐาน!$C$22*12*E18,0) -> 57364.443 | K18: =IF(AND(D18="รับราชการ",A18>=สมมติฐาน!$C$27,A18<สมมติฐาน!$C$27+สมมติฐาน!$C$28),สมมติฐาน!$C$25*สมมติฐาน!$C$26*E18,0) -> 59754.628 | L18: =G18*สมมติฐาน!$C$20 -> 10346.99 | M18: =IF(D18="รับราชการ",สมมติฐาน!$C$30+IF(AND(A18>=สมมติฐาน!$C$32,A18<=สมมติฐาน!$C$33),สมมติฐาน!$C$31,0),0) -> 4 | N18: =IF(AND(A18>=สมมติฐาน!$C$35,A18<=สมมติฐาน!$C$36),สมมติฐาน!$C$34,0)+IF(D18="รับราชการ",0,สมมติฐาน!$C$37) -> 2 | O18: =(1+สมมติฐาน!$B$43)^(A18-1)*(1+สมมติฐาน!$B$44)^(A18-1) -> 1.4282462 | P18: =(M18*สมมติฐาน!$C$38+N18*สมมติฐาน!$C$39)*O18 -> 117116.19 | Q18: =IF(D18="รับราชการ",0,$AB$6*12*(1+สมมติฐาน!$B$46)^(A18-35-1)) -> 0 | R18: =IF(C18=สมมติฐาน!$C$8,$AB$7,0)+IF(C18=65,$AB$9,0)+IF(A18=58,$AB$10+$AB$11,0) -> 0 | S18: =G18+H18+I18+J18+K18+L18+P18+Q18+R18 -> 656920.79 | T18: =S18/E18 -> 549681.93 | U18: =1/(1+สมมติฐาน!$B$45)^(A18-1) -> 0.70258674 | V18: =S18*U18 -> 461543.83
A19: 11 | B19: =สมมติฐาน!$B$42+A19-1 -> 2579 | C19: =สมมติฐาน!$C$7+A19-1 -> 35 | D19: =IF(C19<สมมติฐาน!$C$8,"รับราชการ","รับบำนาญ") -> รับราชการ | E19: =(1+สมมติฐาน!$B$43)^(A19-1) -> 1.2189944 | F19: =IF(D19="รับราชการ",สมมติฐาน!$C$13*(1+สมมติฐาน!$C$15)^(A19-1)*E19,0) -> 30234.823 | G19: =F19*12 -> 362817.88 | H19: =IF(D19="รับราชการ",IF(A19>=สมมติฐาน!$C$19,สมมติฐาน!$C$18,IF(A19>=สมมติฐาน!$C$17,สมมติฐาน!$C$16,0))*12*E19,0) -> 51197.766 | I19: =G19*สมมติฐาน!$C$21 -> 18140.894 | J19: =IF(AND(D19="รับราชการ",A19<=สมมติฐาน!$C$23),สมมติฐาน!$C$22*12*E19,0) -> 0 | K19: =IF(AND(D19="รับราชการ",A19>=สมมติฐาน!$C$27,A19<สมมติฐาน!$C$27+สมมติฐาน!$C$28),สมมติฐาน!$C$25*สมมติฐาน!$C$26*E19,0) -> 60949.721 | L19: =G19*สมมติฐาน!$C$20 -> 10884.536 | M19: =IF(D19="รับราชการ",สมมติฐาน!$C$30+IF(AND(A19>=สมมติฐาน!$C$32,A19<=สมมติฐาน!$C$33),สมมติฐาน!$C$31,0),0) -> 4 | N19: =IF(AND(A19>=สมมติฐาน!$C$35,A19<=สมมติฐาน!$C$36),สมมติฐาน!$C$34,0)+IF(D19="รับราชการ",0,สมมติฐาน!$C$37) -> 2 | O19: =(1+สมมติฐาน!$B$43)^(A19-1)*(1+สมมติฐาน!$B$44)^(A19-1) -> 1.4859474 | P19: =(M19*สมมติฐาน!$C$38+N19*สมมติฐาน!$C$39)*O19 -> 121847.69 | Q19: =IF(D19="รับราชการ",0,$AB$6*12*(1+สมมติฐาน!$B$46)^(A19-35-1)) -> 0 | R19: =IF(C19=สมมติฐาน!$C$8,$AB$7,0)+IF(C19=65,$AB$9,0)+IF(A19=58,$AB$10+$AB$11,0) -> 0 | S19: =G19+H19+I19+J19+K19+L19+P19+Q19+R19 -> 625838.48 | T19: =S19/E19 -> 513405.54 | U19: =1/(1+สมมติฐาน!$B$45)^(A19-1) -> 0.67556417 | V19: =S19*U19 -> 422794.05
A20: 12 | B20: =สมมติฐาน!$B$42+A20-1 -> 2580 | C20: =สมมติฐาน!$C$7+A20-1 -> 36 | D20: =IF(C20<สมมติฐาน!$C$8,"รับราชการ","รับบำนาญ") -> รับราชการ | E20: =(1+สมมติฐาน!$B$43)^(A20-1) -> 1.2433743 | F20: =IF(D20="รับราชการ",สมมติฐาน!$C$13*(1+สมมติฐาน!$C$15)^(A20-1)*E20,0) -> 31805.582 | G20: =F20*12 -> 381666.98 | H20: =IF(D20="รับราชการ",IF(A20>=สมมติฐาน!$C$19,สมมติฐาน!$C$18,IF(A20>=สมมติฐาน!$C$17,สมมติฐาน!$C$16,0))*12*E20,0) -> 52221.721 | I20: =G20*สมมติฐาน!$C$21 -> 19083.349 | J20: =IF(AND(D20="รับราชการ",A20<=สมมติฐาน!$C$23),สมมติฐาน!$C$22*12*E20,0) -> 0 | K20: =IF(AND(D20="รับราชการ",A20>=สมมติฐาน!$C$27,A20<สมมติฐาน!$C$27+สมมติฐาน!$C$28),สมมติฐาน!$C$25*สมมติฐาน!$C$26*E20,0) -> 62168.715 | L20: =G20*สมมติฐาน!$C$20 -> 11450.009 | M20: =IF(D20="รับราชการ",สมมติฐาน!$C$30+IF(AND(A20>=สมมติฐาน!$C$32,A20<=สมมติฐาน!$C$33),สมมติฐาน!$C$31,0),0) -> 4 | N20: =IF(AND(A20>=สมมติฐาน!$C$35,A20<=สมมติฐาน!$C$36),สมมติฐาน!$C$34,0)+IF(D20="รับราชการ",0,สมมติฐาน!$C$37) -> 2 | O20: =(1+สมมติฐาน!$B$43)^(A20-1)*(1+สมมติฐาน!$B$44)^(A20-1) -> 1.5459797 | P20: =(M20*สมมติฐาน!$C$38+N20*สมมติฐาน!$C$39)*O20 -> 126770.33 | Q20: =IF(D20="รับราชการ",0,$AB$6*12*(1+สมมติฐาน!$B$46)^(A20-35-1)) -> 0 | R20: =IF(C20=สมมติฐาน!$C$8,$AB$7,0)+IF(C20=65,$AB$9,0)+IF(A20=58,$AB$10+$AB$11,0) -> 0 | S20: =G20+H20+I20+J20+K20+L20+P20+Q20+R20 -> 653361.11 | T20: =S20/E20 -> 525474.19 | U20: =1/(1+สมมติฐาน!$B$45)^(A20-1) -> 0.64958093 | V20: =S20*U20 -> 424410.92
A21: 13 | B21: =สมมติฐาน!$B$42+A21-1 -> 2581 | C21: =สมมติฐาน!$C$7+A21-1 -> 37 | D21: =IF(C21<สมมติฐาน!$C$8,"รับราชการ","รับบำนาญ") -> รับราชการ | E21: =(1+สมมติฐาน!$B$43)^(A21-1) -> 1.2682418 | F21: =IF(D21="รับราชการ",สมมติฐาน!$C$13*(1+สมมติฐาน!$C$15)^(A21-1)*E21,0) -> 33457.944 | G21: =F21*12 -> 401495.33 | H21: =IF(D21="รับราชการ",IF(A21>=สมมติฐาน!$C$19,สมมติฐาน!$C$18,IF(A21>=สมมติฐาน!$C$17,สมมติฐาน!$C$16,0))*12*E21,0) -> 53266.155 | I21: =G21*สมมติฐาน!$C$21 -> 20074.766 | J21: =IF(AND(D21="รับราชการ",A21<=สมมติฐาน!$C$23),สมมติฐาน!$C$22*12*E21,0) -> 0 | K21: =IF(AND(D21="รับราชการ",A21>=สมมติฐาน!$C$27,A21<สมมติฐาน!$C$27+สมมติฐาน!$C$28),สมมติฐาน!$C$25*สมมติฐาน!$C$26*E21,0) -> 63412.09 | L21: =G21*สมมติฐาน!$C$20 -> 12044.86 | M21: =IF(D21="รับราชการ",สมมติฐาน!$C$30+IF(AND(A21>=สมมติฐาน!$C$32,A21<=สมมติฐาน!$C$33),สมมติฐาน!$C$31,0),0) -> 4 | N21: =IF(AND(A21>=สมมติฐาน!$C$35,A21<=สมมติฐาน!$C$36),สมมติฐาน!$C$34,0)+IF(D21="รับราชการ",0,สมมติฐาน!$C$37) -> 2 | O21: =(1+สมมติฐาน!$B$43)^(A21-1)*(1+สมมติฐาน!$B$44)^(A21-1) -> 1.6084372 | P21: =(M21*สมมติฐาน!$C$38+N21*สมมติฐาน!$C$39)*O21 -> 131891.85 | Q21: =IF(D21="รับราชการ",0,$AB$6*12*(1+สมมติฐาน!$B$46)^(A21-35-1)) -> 0 | R21: =IF(C21=สมมติฐาน!$C$8,$AB$7,0)+IF(C21=65,$AB$9,0)+IF(A21=58,$AB$10+$AB$11,0) -> 0 | S21: =G21+H21+I21+J21+K21+L21+P21+Q21+R21 -> 682185.05 | T21: =S21/E21 -> 537898.26 | U21: =1/(1+สมมติฐาน!$B$45)^(A21-1) -> 0.62459705 | V21: =S21*U21 -> 426090.77
A22: 14 | B22: =สมมติฐาน!$B$42+A22-1 -> 2582 | C22: =สมมติฐาน!$C$7+A22-1 -> 38 | D22: =IF(C22<สมมติฐาน!$C$8,"รับราชการ","รับบำนาญ") -> รับราชการ | E22: =(1+สมมติฐาน!$B$43)^(A22-1) -> 1.2936066 | F22: =IF(D22="รับราชการ",สมมติฐาน!$C$13*(1+สมมติฐาน!$C$15)^(A22-1)*E22,0) -> 35196.149 | G22: =F22*12 -> 422353.79 | H22: =IF(D22="รับราชการ",IF(A22>=สมมติฐาน!$C$19,สมมติฐาน!$C$18,IF(A22>=สมมติฐาน!$C$17,สมมติฐาน!$C$16,0))*12*E22,0) -> 54331.478 | I22: =G22*สมมติฐาน!$C$21 -> 21117.69 | J22: =IF(AND(D22="รับราชการ",A22<=สมมติฐาน!$C$23),สมมติฐาน!$C$22*12*E22,0) -> 0 | K22: =IF(AND(D22="รับราชการ",A22>=สมมติฐาน!$C$27,A22<สมมติฐาน!$C$27+สมมติฐาน!$C$28),สมมติฐาน!$C$25*สมมติฐาน!$C$26*E22,0) -> 64680.332 | L22: =G22*สมมติฐาน!$C$20 -> 12670.614 | M22: =IF(D22="รับราชการ",สมมติฐาน!$C$30+IF(AND(A22>=สมมติฐาน!$C$32,A22<=สมมติฐาน!$C$33),สมมติฐาน!$C$31,0),0) -> 4 | N22: =IF(AND(A22>=สมมติฐาน!$C$35,A22<=สมมติฐาน!$C$36),สมมติฐาน!$C$34,0)+IF(D22="รับราชการ",0,สมมติฐาน!$C$37) -> 2 | O22: =(1+สมมติฐาน!$B$43)^(A22-1)*(1+สมมติฐาน!$B$44)^(A22-1) -> 1.6734181 | P22: =(M22*สมมติฐาน!$C$38+N22*สมมติฐาน!$C$39)*O22 -> 137220.29 | Q22: =IF(D22="รับราชการ",0,$AB$6*12*(1+สมมติฐาน!$B$46)^(A22-35-1)) -> 0 | R22: =IF(C22=สมมติฐาน!$C$8,$AB$7,0)+IF(C22=65,$AB$9,0)+IF(A22=58,$AB$10+$AB$11,0) -> 0 | S22: =G22+H22+I22+J22+K22+L22+P22+Q22+R22 -> 712374.19 | T22: =S22/E22 -> 550688.42 | U22: =1/(1+สมมติฐาน!$B$45)^(A22-1) -> 0.60057409 | V22: =S22*U22 -> 427833.48
A23: 15 | B23: =สมมติฐาน!$B$42+A23-1 -> 2583 | C23: =สมมติฐาน!$C$7+A23-1 -> 39 | D23: =IF(C23<สมมติฐาน!$C$8,"รับราชการ","รับบำนาญ") -> รับราชการ | E23: =(1+สมมติฐาน!$B$43)^(A23-1) -> 1.3194788 | F23: =IF(D23="รับราชการ",สมมติฐาน!$C$13*(1+สมมติฐาน!$C$15)^(A23-1)*E23,0) -> 37024.658 | G23: =F23*12 -> 444295.9 | H23: =IF(D23="รับราชการ",IF(A23>=สมมติฐาน!$C$19,สมมติฐาน!$C$18,IF(A23>=สมมติฐาน!$C$17,สมมติฐาน!$C$16,0))*12*E23,0) -> 55418.108 | I23: =G23*สมมติฐาน!$C$21 -> 22214.795 | J23: =IF(AND(D23="รับราชการ",A23<=สมมติฐาน!$C$23),สมมติฐาน!$C$22*12*E23,0) -> 0 | K23: =IF(AND(D23="รับราชการ",A23>=สมมติฐาน!$C$27,A23<สมมติฐาน!$C$27+สมมติฐาน!$C$28),สมมติฐาน!$C$25*สมมติฐาน!$C$26*E23,0) -> 65973.938 | L23: =G23*สมมติฐาน!$C$20 -> 13328.877 | M23: =IF(D23="รับราชการ",สมมติฐาน!$C$30+IF(AND(A23>=สมมติฐาน!$C$32,A23<=สมมติฐาน!$C$33),สมมติฐาน!$C$31,0),0) -> 4 | N23: =IF(AND(A23>=สมมติฐาน!$C$35,A23<=สมมติฐาน!$C$36),สมมติฐาน!$C$34,0)+IF(D23="รับราชการ",0,สมมติฐาน!$C$37) -> 2 | O23: =(1+สมมติฐาน!$B$43)^(A23-1)*(1+สมมติฐาน!$B$44)^(A23-1) -> 1.7410242 | P23: =(M23*สมมติฐาน!$C$38+N23*สมมติฐาน!$C$39)*O23 -> 142763.98 | Q23: =IF(D23="รับราชการ",0,$AB$6*12*(1+สมมติฐาน!$B$46)^(A23-35-1)) -> 0 | R23: =IF(C23=สมมติฐาน!$C$8,$AB$7,0)+IF(C23=65,$AB$9,0)+IF(A23=58,$AB$10+$AB$11,0) -> 0 | S23: =G23+H23+I23+J23+K23+L23+P23+Q23+R23 -> 743995.6 | T23: =S23/E23 -> 563855.69 | U23: =1/(1+สมมติฐาน!$B$45)^(A23-1) -> 0.57747508 | V23: =S23*U23 -> 429638.92
... A66: 58 | B66: =สมมติฐาน!$B$42+A66-1 -> 2626 | C66: =สมมติฐาน!$C$7+A66-1 -> 82 | D66: =IF(C66<สมมติฐาน!$C$8,"รับราชการ","รับบำนาญ") -> รับบำนาญ | E66: =(1+สมมติฐาน!$B$43)^(A66-1) -> 3.0917886 | F66: =IF(D66="รับราชการ",สมมติฐาน!$C$13*(1+สมมติฐาน!$C$15)^(A66-1)*E66,0) -> 0 | G66: =F66*12 -> 0 | H66: =IF(D66="รับราชการ",IF(A66>=สมมติฐาน!$C$19,สมมติฐาน!$C$18,IF(A66>=สมมติฐาน!$C$17,สมมติฐาน!$C$16,0))*12*E66,0) -> 0 | I66: =G66*สมมติฐาน!$C$21 -> 0 | J66: =IF(AND(D66="รับราชการ",A66<=สมมติฐาน!$C$23),สมมติฐาน!$C$22*12*E66,0) -> 0 | K66: =IF(AND(D66="รับราชการ",A66>=สมมติฐาน!$C$27,A66<สมมติฐาน!$C$27+สมมติฐาน!$C$28),สมมติฐาน!$C$25*สมมติฐาน!$C$26*E66,0) -> 0 | L66: =G66*สมมติฐาน!$C$20 -> 0 | M66: =IF(D66="รับราชการ",สมมติฐาน!$C$30+IF(AND(A66>=สมมติฐาน!$C$32,A66<=สมมติฐาน!$C$33),สมมติฐาน!$C$31,0),0) -> 0 | N66: =IF(AND(A66>=สมมติฐาน!$C$35,A66<=สมมติฐาน!$C$36),สมมติฐาน!$C$34,0)+IF(D66="รับราชการ",0,สมมติฐาน!$C$37) -> 2 | O66: =(1+สมมติฐาน!$B$43)^(A66-1)*(1+สมมติฐาน!$B$44)^(A66-1) -> 9.5591567 | P66: =(M66*สมมติฐาน!$C$38+N66*สมมติฐาน!$C$39)*O66 -> 477957.83 | Q66: =IF(D66="รับราชการ",0,$AB$6*12*(1+สมมติฐาน!$B$46)^(A66-35-1)) -> 775907.72 | R66: =IF(C66=สมมติฐาน!$C$8,$AB$7,0)+IF(C66=65,$AB$9,0)+IF(A66=58,$AB$10+$AB$11,0) -> 1633746.2 | S66: =G66+H66+I66+J66+K66+L66+P66+Q66+R66 -> 2887611.8 | T66: =S66/E66 -> 933961.59 | U66: =1/(1+สมมติฐาน!$B$45)^(A66-1) -> 0.10693002 | V66: =S66*U66 -> 308772.4
A67: รวม | G67: =SUM(G9:G66) -> 20564828 | H67: =SUM(H9:H66) -> 2471806.9 | I67: =SUM(I9:I66) -> 1028241.4 | J67: =SUM(J9:J66) -> 525586.61 | K67: =SUM(K9:K66) -> 1229800.8 | L67: =SUM(L9:L66) -> 616944.84 | P67: =SUM(P9:P66) -> 10898236 | Q67: =SUM(Q9:Q66) -> 17845878 | R67: =SUM(R9:R66) -> 2133746.2 | S67: =SUM(S9:S66) -> 57315069 | T67: =SUM(T9:T66) -> 31107527 | V67: =SUM(V9:V66) -> 18741741

Sheet 3_สูง
A1: กรณี สูง — ข้าราชการผู้ใหญ่ เทียบซี 9–10 — เชี่ยวชาญ / อำนวยการสูง
A2: ทุกจำนวนเงินเป็น 'ตัวเงินจริง ณ ปีนั้น' (nominal) เว้นคอลัมน์ที่ระบุไว้ • แก้สมมติฐานได้ที่แผ่น 'สมมติฐาน' เท่านั้น • ตัวแปรบำนาญคำนวณไว้ทางขวามือ | Y2: ตัวแปรบำนาญ (คำนวณจากตารางด้านล่าง)
Y3: เงินเดือนเฉลี่ย 60 เดือนสุดท้าย | AB3: =AVERAGE(F40:F44) -> 132840.47
Y4: บำนาญรายเดือน | AB4: =MIN(AB3*สมมติฐาน!$D$10/สมมติฐาน!$B$48,AB3*สมมติฐาน!$B$47) -> 92988.326
Y5: ช.ค.บ. รายเดือน | AB5: =MAX(0,สมมติฐาน!$B$49-AB4) -> 0
Y6: บำนาญ + ช.ค.บ. รายเดือน | AB6: =AB4+AB5 -> 92988.326
Y7: บำเหน็จดำรงชีพ ครั้งที่ 1 (ปีเกษียณ) | AB7: =MIN(AB4*สมมติฐาน!$B$52,สมมติฐาน!$B$50) -> 200000
A8: ปีที่ | B8: ปี พ.ศ. | C8: อายุ | D8: สถานะ | E8: ดัชนีราคา | F8: เงินเดือน (บาท/เดือน) | G8: เงินเดือน รายปี | H8: เงินประจำตำแหน่ง + ค่าตอบแทน | I8: เงินสมทบ กบข. (รัฐจ่าย) | J8: ค่าเช่าบ้าน | K8: ค่าการศึกษา บุตร | L8: ค่าตอบแทน/ สวัสดิการอื่น | M8: ผู้ใช้สิทธิ ไม่สูงอายุ | N8: ผู้ใช้สิทธิ สูงอายุ | O8: ดัชนี ค่ารักษา | P8: ค่ารักษาพยาบาล | Q8: บำนาญ + ช.ค.บ. | R8: เงินก้อน (ดำรงชีพ/ตกทอด/ค่าทำศพ) | S8: รวมต้นทุนปีนั้น (ตัวเงินจริง) | T8: รวม ณ ราคาปี 2569 | U8: ตัวคิดลด | V8: มูลค่าปัจจุบัน | Y8: บำเหน็จดำรงชีพ รวมทั้งหมด | AB8: =MIN(AB4*สมมติฐาน!$B$52,สมมติฐาน!$B$51) -> 500000
A9: 1 | B9: =สมมติฐาน!$B$42+A9-1 -> 2569 | C9: =สมมติฐาน!$D$7+A9-1 -> 24 | D9: =IF(C9<สมมติฐาน!$D$8,"รับราชการ","รับบำนาญ") -> รับราชการ | E9: =(1+สมมติฐาน!$B$43)^(A9-1) -> 1 | F9: =IF(D9="รับราชการ",สมมติฐาน!$D$13*(1+สมมติฐาน!$D$15)^(A9-1)*E9,0) -> 21180 | G9: =F9*12 -> 254160 | H9: =IF(D9="รับราชการ",IF(A9>=สมมติฐาน!$D$19,สมมติฐาน!$D$18,IF(A9>=สมมติฐาน!$D$17,สมมติฐาน!$D$16,0))*12*E9,0) -> 0 | I9: =G9*สมมติฐาน!$D$21 -> 12708 | J9: =IF(AND(D9="รับราชการ",A9<=สมมติฐาน!$D$23),สมมติฐาน!$D$22*12*E9,0) -> 60000 | K9: =IF(AND(D9="รับราชการ",A9>=สมมติฐาน!$D$27,A9<สมมติฐาน!$D$27+สมมติฐาน!$D$28),สมมติฐาน!$D$25*สมมติฐาน!$D$26*E9,0) -> 0 | L9: =G9*สมมติฐาน!$D$20 -> 10166.4 | M9: =IF(D9="รับราชการ",สมมติฐาน!$D$30+IF(AND(A9>=สมมติฐาน!$D$32,A9<=สมมติฐาน!$D$33),สมมติฐาน!$D$31,0),0) -> 2 | N9: =IF(AND(A9>=สมมติฐาน!$D$35,A9<=สมมติฐาน!$D$36),สมมติฐาน!$D$34,0)+IF(D9="รับราชการ",0,สมมติฐาน!$D$37) -> 2 | O9: =(1+สมมติฐาน!$B$43)^(A9-1)*(1+สมมติฐาน!$B$44)^(A9-1) -> 1 | P9: =(M9*สมมติฐาน!$D$38+N9*สมมติฐาน!$D$39)*O9 -> 74000 | Q9: =IF(D9="รับราชการ",0,$AB$6*12*(1+สมมติฐาน!$B$46)^(A9-36-1)) -> 0 | R9: =IF(C9=สมมติฐาน!$D$8,$AB$7,0)+IF(C9=65,$AB$9,0)+IF(A9=62,$AB$10+$AB$11,0) -> 0 | S9: =G9+H9+I9+J9+K9+L9+P9+Q9+R9 -> 411034.4 | T9: =S9/E9 -> 411034.4 | U9: =1/(1+สมมติฐาน!$B$45)^(A9-1) -> 1 | V9: =S9*U9 -> 411034.4 | Y9: บำเหน็จดำรงชีพ ครั้งที่ 2 (อายุ 65) | AB9: =AB8-AB7 -> 300000
A10: 2 | B10: =สมมติฐาน!$B$42+A10-1 -> 2570 | C10: =สมมติฐาน!$D$7+A10-1 -> 25 | D10: =IF(C10<สมมติฐาน!$D$8,"รับราชการ","รับบำนาญ") -> รับราชการ | E10: =(1+สมมติฐาน!$B$43)^(A10-1) -> 1.02 | F10: =IF(D10="รับราชการ",สมมติฐาน!$D$13*(1+สมมติฐาน!$D$15)^(A10-1)*E10,0) -> 22389.745 | G10: =F10*12 -> 268676.94 | H10: =IF(D10="รับราชการ",IF(A10>=สมมติฐาน!$D$19,สมมติฐาน!$D$18,IF(A10>=สมมติฐาน!$D$17,สมมติฐาน!$D$16,0))*12*E10,0) -> 0 | I10: =G10*สมมติฐาน!$D$21 -> 13433.847 | J10: =IF(AND(D10="รับราชการ",A10<=สมมติฐาน!$D$23),สมมติฐาน!$D$22*12*E10,0) -> 61200 | K10: =IF(AND(D10="รับราชการ",A10>=สมมติฐาน!$D$27,A10<สมมติฐาน!$D$27+สมมติฐาน!$D$28),สมมติฐาน!$D$25*สมมติฐาน!$D$26*E10,0) -> 0 | L10: =G10*สมมติฐาน!$D$20 -> 10747.078 | M10: =IF(D10="รับราชการ",สมมติฐาน!$D$30+IF(AND(A10>=สมมติฐาน!$D$32,A10<=สมมติฐาน!$D$33),สมมติฐาน!$D$31,0),0) -> 2 | N10: =IF(AND(A10>=สมมติฐาน!$D$35,A10<=สมมติฐาน!$D$36),สมมติฐาน!$D$34,0)+IF(D10="รับราชการ",0,สมมติฐาน!$D$37) -> 2 | O10: =(1+สมมติฐาน!$B$43)^(A10-1)*(1+สมมติฐาน!$B$44)^(A10-1) -> 1.0404 | P10: =(M10*สมมติฐาน!$D$38+N10*สมมติฐาน!$D$39)*O10 -> 76989.6 | Q10: =IF(D10="รับราชการ",0,$AB$6*12*(1+สมมติฐาน!$B$46)^(A10-36-1)) -> 0 | R10: =IF(C10=สมมติฐาน!$D$8,$AB$7,0)+IF(C10=65,$AB$9,0)+IF(A10=62,$AB$10+$AB$11,0) -> 0 | S10: =G10+H10+I10+J10+K10+L10+P10+Q10+R10 -> 431047.47 | T10: =S10/E10 -> 422595.55 | U10: =1/(1+สมมติฐาน!$B$45)^(A10-1) -> 0.96153846 | V10: =S10*U10 -> 414468.72 | Y10: บำเหน็จตกทอด (ปีเสียชีวิต) | AB10: =MAX(0,AB6*สมมติฐาน!$B$53-AB8) -> 2289649.8
